Script started on 2021-04-18 19:53:20+07:00 [TERM="xterm-256color" TTY="/dev/pts/0" COLUMNS="125" LINES="14"]
^[[F]0;slv@slvmwr: ~/doSumn[01;32mslv@slvmwr[00m:[01;34m~/doSumn[00m$ cds [K[K script
]0;slv@slvmwr: ~/doSumn/script[01;32mslv@slvmwr[00m:[01;34m~/doSumn/script[00m$ cd scriptpython3 main.pytext.pymain.py[6Pcd scriptpython3 main.pytezt.pyxt.pyzt.pyxt.py[10Pclearpython3 main.pytezt.pyxt.pyzt.pyst.pyxt.pymain.py[1Psum.pytest.pyxt.pyip3 install networkx[6Python3 main.py[6Pcd scriptpython3 main.py[10Pclearpython3 main.py[6Pcd scriptpython3 main.py[10Pclearpython3 main.py[1@'[C[C[C[C[C[C[C[C[C[C[C[C[C[C[C[10P0-9l'p'python3 main.py[10P0-9l'ppython3 main.py[1Ptestpymain.py[10Pclearpython3 main.py[6Pcd scriptpython3 main.pytest.pymain.pytest.py[6Pcd scriptpython3 test.py[1Ppymain.pyip3 install sumy[2Python3 main.py''''''''''''''''''''''''''''''''''''''''''''''''''''''''''''''''''''[C[C[C[C[C[C[C[C[C[C[C[C[C[C[C[C[C[C[C[C[C[C[C[C[C[C[C[Cpython3 main.py[K''''''''''''''''''''''''''''''''''''''''''''''''''''''''''''''''''''[C[C[C[C[C[C[C[C[C[C[C[C[C[C[C[C[C[C[C[C[C[C[C[C[C[C[C[Cpython3 main.py[K''''''''''''''''''''''''''''''''''''''''''''''''''''''''''''''''''''[C[C[C[C[C[C[C[C[C[C[C[C[C[C[C[C[C[C[C[C[C[C[C[C[C[C[C[Cpython3 main.py[K[6Pcd scriptpython3 main.pyip3 install lexrank[11Pflask runexport FLASK_DEBUG=1clear[Kexport FLASK_DEBUG=1[11Pflask runexport FLASK_DEBUG=1clear[Kexport FLASK_DEBUG=1
]0;slv@slvmwr: ~/doSumn/script[01;32mslv@slvmwr[00m:[01;34m~/doSumn/script[00m$ export FLASK_DEBUG=1[Kexport FLASK_DEBUG=1[11Pcd scriptexport FLASK_DEBUG=1[Kexport FLASK_DEBUG=1[11Pcd script[K[K[K[K[K[K[K[K[Kflask run
 * Environment: production
[31m   WARNING: This is a development server. Do not use it in a production deployment.[0m
[2m   Use a production WSGI server instead.[0m
 * Debug mode: on
 * Running on http://127.0.0.1:5000/ (Press CTRL+C to quit)
 * Restarting with stat
 * Debugger is active!
 * Debugger PIN: 263-977-074
127.0.0.1 - - [18/Apr/2021 19:55:47] "[37mGET / HTTP/1.1[0m" 200 -
127.0.0.1 - - [18/Apr/2021 19:55:48] "[37mGET /static/style.css HTTP/1.1[0m" 200 -
127.0.0.1 - - [18/Apr/2021 19:55:48] "[37mGET /static/fasilkom.png HTTP/1.1[0m" 200 -
127.0.0.1 - - [18/Apr/2021 19:55:48] "[33mGET /favicon.ico HTTP/1.1[0m" 404 -
 * Detected change in '/home/slv/doSumn/script/app.py', reloading
 * Restarting with stat
 * Debugger is active!
 * Debugger PIN: 263-977-074
127.0.0.1 - - [18/Apr/2021 19:56:16] "[37mGET / HTTP/1.1[0m" 200 -
127.0.0.1 - - [18/Apr/2021 19:56:27] "[35m[1mGET /summary HTTP/1.1[0m" 500 -
Traceback (most recent call last):
  File "/home/slv/.local/lib/python3.8/site-packages/flask/app.py", line 2464, in __call__
    return self.wsgi_app(environ, start_response)
  File "/home/slv/.local/lib/python3.8/site-packages/flask/app.py", line 2450, in wsgi_app
    response = self.handle_exception(e)
  File "/home/slv/.local/lib/python3.8/site-packages/flask/app.py", line 1867, in handle_exception
    reraise(exc_type, exc_value, tb)
  File "/home/slv/.local/lib/python3.8/site-packages/flask/_compat.py", line 39, in reraise
    raise value
  File "/home/slv/.local/lib/python3.8/site-packages/flask/app.py", line 2447, in wsgi_app
    response = self.full_dispatch_request()
  File "/home/slv/.local/lib/python3.8/site-packages/flask/app.py", line 1952, in full_dispatch_request
    rv = self.handle_user_exception(e)
  File "/home/slv/.local/lib/python3.8/site-packages/flask/app.py", line 1821, in handle_user_exception
    reraise(exc_type, exc_value, tb)
  File "/home/slv/.local/lib/python3.8/site-packages/flask/_compat.py", line 39, in reraise
    raise value
  File "/home/slv/.local/lib/python3.8/site-packages/flask/app.py", line 1950, in full_dispatch_request
    rv = self.dispatch_request()
  File "/home/slv/.local/lib/python3.8/site-packages/flask/app.py", line 1936, in dispatch_request
    return self.view_functions[rule.endpoint](**req.view_args)
  File "/home/slv/doSumn/script/app.py", line 13, in summ
    return render_template("home.html", data="hello")
  File "/home/slv/.local/lib/python3.8/site-packages/flask/templating.py", line 138, in render_template
    ctx.app.jinja_env.get_or_select_template(template_name_or_list),
  File "/home/slv/.local/lib/python3.8/site-packages/jinja2/environment.py", line 930, in get_or_select_template
    return self.get_template(template_name_or_list, parent, globals)
  File "/home/slv/.local/lib/python3.8/site-packages/jinja2/environment.py", line 883, in get_template
    return self._load_template(name, self.make_globals(globals))
  File "/home/slv/.local/lib/python3.8/site-packages/jinja2/environment.py", line 857, in _load_template
    template = self.loader.load(self, name, globals)
  File "/home/slv/.local/lib/python3.8/site-packages/jinja2/loaders.py", line 115, in load
    source, filename, uptodate = self.get_source(environment, name)
  File "/home/slv/.local/lib/python3.8/site-packages/flask/templating.py", line 60, in get_source
    return self._get_source_fast(environment, template)
  File "/home/slv/.local/lib/python3.8/site-packages/flask/templating.py", line 89, in _get_source_fast
    raise TemplateNotFound(template)
jinja2.exceptions.TemplateNotFound: home.html
127.0.0.1 - - [18/Apr/2021 19:56:27] "[37mGET /summary?__debugger__=yes&cmd=resource&f=jquery.js HTTP/1.1[0m" 200 -
127.0.0.1 - - [18/Apr/2021 19:56:27] "[37mGET /summary?__debugger__=yes&cmd=resource&f=style.css HTTP/1.1[0m" 200 -
127.0.0.1 - - [18/Apr/2021 19:56:27] "[37mGET /summary?__debugger__=yes&cmd=resource&f=debugger.js HTTP/1.1[0m" 200 -
127.0.0.1 - - [18/Apr/2021 19:56:27] "[37mGET /summary?__debugger__=yes&cmd=resource&f=console.png HTTP/1.1[0m" 200 -
127.0.0.1 - - [18/Apr/2021 19:56:27] "[37mGET /summary?__debugger__=yes&cmd=resource&f=console.png HTTP/1.1[0m" 200 -
 * Detected change in '/home/slv/doSumn/script/app.py', reloading
 * Restarting with stat
 * Debugger is active!
 * Debugger PIN: 263-977-074
127.0.0.1 - - [18/Apr/2021 19:56:57] "[37mGET /summary HTTP/1.1[0m" 200 -
 * Detected change in '/home/slv/doSumn/script/app.py', reloading
 * Restarting with stat
 * Debugger is active!
 * Debugger PIN: 263-977-074
127.0.0.1 - - [18/Apr/2021 19:57:11] "[37mGET /summary HTTP/1.1[0m" 200 -
127.0.0.1 - - [18/Apr/2021 19:57:11] "[37mGET /summary HTTP/1.1[0m" 200 -
127.0.0.1 - - [18/Apr/2021 20:08:52] "[37mGET /summary HTTP/1.1[0m" 200 -
127.0.0.1 - - [18/Apr/2021 20:08:52] "[37mGET /summary HTTP/1.1[0m" 200 -
127.0.0.1 - - [18/Apr/2021 20:08:56] "[37mGET / HTTP/1.1[0m" 200 -
127.0.0.1 - - [18/Apr/2021 20:08:58] "[37mGET /summary HTTP/1.1[0m" 200 -
 * Detected change in '/home/slv/doSumn/script/main.py', reloading
 * Restarting with stat
 * Debugger is active!
 * Debugger PIN: 263-977-074
127.0.0.1 - - [18/Apr/2021 20:10:35] "[35m[1mGET /summary HTTP/1.1[0m" 500 -
Traceback (most recent call last):
  File "/home/slv/.local/lib/python3.8/site-packages/flask/_compat.py", line 39, in reraise
    raise value
  File "/home/slv/doSumn/script/app.py", line 2, in <module>
    import main
File "/home/slv/doSumn/script/main.py", line 87
    text = "Lorem ipsum dolor sit amet, consectetur adipiscing elit. Vestibulum congue tellus ut egestas lobortis. Curabitur ullamcorper mauris ut leo consequat, in lacinia mauris volutpat. Ut id feugiat mauris. Cras non risus eros. Interdum et malesuada fames ac ante ipsum primis in faucibus. Mauris sed ligula massa. Suspendisse non erat vel nibh pretium cursus. Suspendisse potenti. Vestibulum lacinia bibendum nunc et lobortis.
                                                                                                                                                                                                                                                                                                                                                                                                                                               ^
SyntaxError: EOL while scanning string literal
127.0.0.1 - - [18/Apr/2021 20:10:35] "[37mGET /summary?__debugger__=yes&cmd=resource&f=style.css HTTP/1.1[0m" 200 -
127.0.0.1 - - [18/Apr/2021 20:10:35] "[37mGET /summary?__debugger__=yes&cmd=resource&f=debugger.js HTTP/1.1[0m" 200 -
127.0.0.1 - - [18/Apr/2021 20:10:35] "[37mGET /summary?__debugger__=yes&cmd=resource&f=jquery.js HTTP/1.1[0m" 200 -
127.0.0.1 - - [18/Apr/2021 20:10:35] "[37mGET /summary?__debugger__=yes&cmd=resource&f=console.png HTTP/1.1[0m" 200 -
127.0.0.1 - - [18/Apr/2021 20:10:35] "[37mGET /summary?__debugger__=yes&cmd=resource&f=console.png HTTP/1.1[0m" 200 -
127.0.0.1 - - [18/Apr/2021 20:11:10] "[37mGET /summary HTTP/1.1[0m" 200 -
127.0.0.1 - - [18/Apr/2021 20:11:10] "[37mGET /summary HTTP/1.1[0m" 200 -
127.0.0.1 - - [18/Apr/2021 20:18:31] "[37mGET /summary HTTP/1.1[0m" 200 -
 * Detected change in '/home/slv/doSumn/script/app.py', reloading
 * Restarting with stat
 * Debugger is active!
 * Debugger PIN: 263-977-074
 * Detected change in '/home/slv/doSumn/script/app.py', reloading
 * Restarting with stat
 * Debugger is active!
 * Debugger PIN: 263-977-074
 * Detected change in '/home/slv/doSumn/script/app.py', reloading
 * Restarting with stat
 * Debugger is active!
 * Debugger PIN: 263-977-074
 * Detected change in '/home/slv/doSumn/script/app.py', reloading
 * Restarting with stat
 * Debugger is active!
 * Debugger PIN: 263-977-074
 * Detected change in '/home/slv/doSumn/script/app.py', reloading
 * Restarting with stat
 * Debugger is active!
 * Debugger PIN: 263-977-074
 * Detected change in '/home/slv/doSumn/script/app.py', reloading
 * Restarting with stat
 * Debugger is active!
 * Debugger PIN: 263-977-074
127.0.0.1 - - [18/Apr/2021 20:24:02] "[37mGET /summary HTTP/1.1[0m" 200 -
127.0.0.1 - - [18/Apr/2021 20:24:05] "[37mGET /summary HTTP/1.1[0m" 200 -
127.0.0.1 - - [18/Apr/2021 20:24:12] "[37mGET /summary HTTP/1.1[0m" 200 -
127.0.0.1 - - [18/Apr/2021 20:24:15] "[37mGET /summary HTTP/1.1[0m" 200 -
127.0.0.1 - - [18/Apr/2021 20:24:16] "[37mGET /summary HTTP/1.1[0m" 200 -
127.0.0.1 - - [18/Apr/2021 20:24:17] "[37mGET /summary HTTP/1.1[0m" 200 -
127.0.0.1 - - [18/Apr/2021 20:24:17] "[37mGET /summary HTTP/1.1[0m" 200 -
 * Detected change in '/home/slv/doSumn/script/app.py', reloading
 * Restarting with stat
 * Debugger is active!
 * Debugger PIN: 263-977-074
127.0.0.1 - - [18/Apr/2021 20:27:28] "[37mGET /summary HTTP/1.1[0m" 200 -
127.0.0.1 - - [18/Apr/2021 20:27:58] "[37mGET /summary HTTP/1.1[0m" 200 -
127.0.0.1 - - [18/Apr/2021 20:30:03] "[37mGET /summary HTTP/1.1[0m" 200 -
127.0.0.1 - - [18/Apr/2021 20:30:05] "[35m[1mPOST /upload HTTP/1.1[0m" 500 -
Traceback (most recent call last):
  File "/home/slv/.local/lib/python3.8/site-packages/flask/app.py", line 2464, in __call__
    return self.wsgi_app(environ, start_response)
  File "/home/slv/.local/lib/python3.8/site-packages/flask/app.py", line 2450, in wsgi_app
    response = self.handle_exception(e)
  File "/home/slv/.local/lib/python3.8/site-packages/flask/app.py", line 1867, in handle_exception
    reraise(exc_type, exc_value, tb)
  File "/home/slv/.local/lib/python3.8/site-packages/flask/_compat.py", line 39, in reraise
    raise value
  File "/home/slv/.local/lib/python3.8/site-packages/flask/app.py", line 2447, in wsgi_app
    response = self.full_dispatch_request()
  File "/home/slv/.local/lib/python3.8/site-packages/flask/app.py", line 1952, in full_dispatch_request
    rv = self.handle_user_exception(e)
  File "/home/slv/.local/lib/python3.8/site-packages/flask/app.py", line 1821, in handle_user_exception
    reraise(exc_type, exc_value, tb)
  File "/home/slv/.local/lib/python3.8/site-packages/flask/_compat.py", line 39, in reraise
    raise value
  File "/home/slv/.local/lib/python3.8/site-packages/flask/app.py", line 1950, in full_dispatch_request
    rv = self.dispatch_request()
  File "/home/slv/.local/lib/python3.8/site-packages/flask/app.py", line 1936, in dispatch_request
    return self.view_functions[rule.endpoint](**req.view_args)
  File "/home/slv/doSumn/script/app.py", line 14, in upload
    file = request.files['file']
  File "/home/slv/.local/lib/python3.8/site-packages/flask/debughelpers.py", line 96, in __getitem__
    return oldcls.__getitem__(self, key)
  File "/home/slv/.local/lib/python3.8/site-packages/werkzeug/datastructures.py", line 442, in __getitem__
    raise exceptions.BadRequestKeyError(key)
werkzeug.exceptions.BadRequestKeyError: 400 Bad Request: The browser (or proxy) sent a request that this server could not understand.
KeyError: 'file'
127.0.0.1 - - [18/Apr/2021 20:30:05] "[37mGET /upload?__debugger__=yes&cmd=resource&f=style.css HTTP/1.1[0m" 200 -
127.0.0.1 - - [18/Apr/2021 20:30:05] "[37mGET /upload?__debugger__=yes&cmd=resource&f=debugger.js HTTP/1.1[0m" 200 -
127.0.0.1 - - [18/Apr/2021 20:30:05] "[37mGET /upload?__debugger__=yes&cmd=resource&f=jquery.js HTTP/1.1[0m" 200 -
127.0.0.1 - - [18/Apr/2021 20:30:05] "[37mGET /upload?__debugger__=yes&cmd=resource&f=console.png HTTP/1.1[0m" 200 -
127.0.0.1 - - [18/Apr/2021 20:30:05] "[37mGET /upload?__debugger__=yes&cmd=resource&f=console.png HTTP/1.1[0m" 200 -
 * Detected change in '/home/slv/doSumn/script/app.py', reloading
 * Restarting with stat
 * Debugger is active!
 * Debugger PIN: 263-977-074
127.0.0.1 - - [18/Apr/2021 20:31:18] "[37mGET /summary HTTP/1.1[0m" 200 -
127.0.0.1 - - [18/Apr/2021 20:31:20] "[35m[1mPOST /upload HTTP/1.1[0m" 500 -
Traceback (most recent call last):
  File "/home/slv/.local/lib/python3.8/site-packages/flask/app.py", line 2464, in __call__
    return self.wsgi_app(environ, start_response)
  File "/home/slv/.local/lib/python3.8/site-packages/flask/app.py", line 2450, in wsgi_app
    response = self.handle_exception(e)
  File "/home/slv/.local/lib/python3.8/site-packages/flask/app.py", line 1867, in handle_exception
    reraise(exc_type, exc_value, tb)
  File "/home/slv/.local/lib/python3.8/site-packages/flask/_compat.py", line 39, in reraise
    raise value
  File "/home/slv/.local/lib/python3.8/site-packages/flask/app.py", line 2447, in wsgi_app
    response = self.full_dispatch_request()
  File "/home/slv/.local/lib/python3.8/site-packages/flask/app.py", line 1952, in full_dispatch_request
    rv = self.handle_user_exception(e)
  File "/home/slv/.local/lib/python3.8/site-packages/flask/app.py", line 1821, in handle_user_exception
    reraise(exc_type, exc_value, tb)
  File "/home/slv/.local/lib/python3.8/site-packages/flask/_compat.py", line 39, in reraise
    raise value
  File "/home/slv/.local/lib/python3.8/site-packages/flask/app.py", line 1950, in full_dispatch_request
    rv = self.dispatch_request()
  File "/home/slv/.local/lib/python3.8/site-packages/flask/app.py", line 1936, in dispatch_request
    return self.view_functions[rule.endpoint](**req.view_args)
  File "/home/slv/doSumn/script/app.py", line 15, in upload
    file = request.files['file']
  File "/home/slv/.local/lib/python3.8/site-packages/flask/debughelpers.py", line 96, in __getitem__
    return oldcls.__getitem__(self, key)
  File "/home/slv/.local/lib/python3.8/site-packages/werkzeug/datastructures.py", line 442, in __getitem__
    raise exceptions.BadRequestKeyError(key)
werkzeug.exceptions.BadRequestKeyError: 400 Bad Request: The browser (or proxy) sent a request that this server could not understand.
KeyError: 'file'
127.0.0.1 - - [18/Apr/2021 20:31:20] "[37mGET /upload?__debugger__=yes&cmd=resource&f=style.css HTTP/1.1[0m" 200 -
127.0.0.1 - - [18/Apr/2021 20:31:20] "[37mGET /upload?__debugger__=yes&cmd=resource&f=jquery.js HTTP/1.1[0m" 200 -
127.0.0.1 - - [18/Apr/2021 20:31:20] "[37mGET /upload?__debugger__=yes&cmd=resource&f=debugger.js HTTP/1.1[0m" 200 -
127.0.0.1 - - [18/Apr/2021 20:31:20] "[37mGET /upload?__debugger__=yes&cmd=resource&f=console.png HTTP/1.1[0m" 200 -
127.0.0.1 - - [18/Apr/2021 20:31:30] "[35m[1mPOST /upload HTTP/1.1[0m" 500 -
Traceback (most recent call last):
  File "/home/slv/.local/lib/python3.8/site-packages/flask/app.py", line 2464, in __call__
    return self.wsgi_app(environ, start_response)
  File "/home/slv/.local/lib/python3.8/site-packages/flask/app.py", line 2450, in wsgi_app
    response = self.handle_exception(e)
  File "/home/slv/.local/lib/python3.8/site-packages/flask/app.py", line 1867, in handle_exception
    reraise(exc_type, exc_value, tb)
  File "/home/slv/.local/lib/python3.8/site-packages/flask/_compat.py", line 39, in reraise
    raise value
  File "/home/slv/.local/lib/python3.8/site-packages/flask/app.py", line 2447, in wsgi_app
    response = self.full_dispatch_request()
  File "/home/slv/.local/lib/python3.8/site-packages/flask/app.py", line 1952, in full_dispatch_request
    rv = self.handle_user_exception(e)
  File "/home/slv/.local/lib/python3.8/site-packages/flask/app.py", line 1821, in handle_user_exception
    reraise(exc_type, exc_value, tb)
  File "/home/slv/.local/lib/python3.8/site-packages/flask/_compat.py", line 39, in reraise
    raise value
  File "/home/slv/.local/lib/python3.8/site-packages/flask/app.py", line 1950, in full_dispatch_request
    rv = self.dispatch_request()
  File "/home/slv/.local/lib/python3.8/site-packages/flask/app.py", line 1936, in dispatch_request
    return self.view_functions[rule.endpoint](**req.view_args)
  File "/home/slv/doSumn/script/app.py", line 15, in upload
    file = request.files['file']
  File "/home/slv/.local/lib/python3.8/site-packages/flask/debughelpers.py", line 96, in __getitem__
    return oldcls.__getitem__(self, key)
  File "/home/slv/.local/lib/python3.8/site-packages/werkzeug/datastructures.py", line 442, in __getitem__
    raise exceptions.BadRequestKeyError(key)
werkzeug.exceptions.BadRequestKeyError: 400 Bad Request: The browser (or proxy) sent a request that this server could not understand.
KeyError: 'file'
127.0.0.1 - - [18/Apr/2021 20:31:30] "[37mGET /upload?__debugger__=yes&cmd=resource&f=style.css HTTP/1.1[0m" 200 -
127.0.0.1 - - [18/Apr/2021 20:31:30] "[37mGET /upload?__debugger__=yes&cmd=resource&f=jquery.js HTTP/1.1[0m" 200 -
127.0.0.1 - - [18/Apr/2021 20:31:30] "[37mGET /upload?__debugger__=yes&cmd=resource&f=debugger.js HTTP/1.1[0m" 200 -
127.0.0.1 - - [18/Apr/2021 20:31:30] "[37mGET /upload?__debugger__=yes&cmd=resource&f=console.png HTTP/1.1[0m" 200 -
 * Detected change in '/home/slv/doSumn/script/app.py', reloading
 * Restarting with stat
 * Debugger is active!
 * Debugger PIN: 263-977-074
 * Detected change in '/home/slv/doSumn/script/app.py', reloading
 * Restarting with stat
 * Debugger is active!
 * Debugger PIN: 263-977-074
 * Detected change in '/home/slv/doSumn/script/app.py', reloading
 * Restarting with stat
 * Debugger is active!
 * Debugger PIN: 263-977-074
127.0.0.1 - - [18/Apr/2021 20:36:05] "[32mPOST /upload HTTP/1.1[0m" 302 -
127.0.0.1 - - [18/Apr/2021 20:36:05] "[31m[1mGET /upload HTTP/1.1[0m" 405 -
127.0.0.1 - - [18/Apr/2021 20:36:11] "[32mPOST /upload HTTP/1.1[0m" 302 -
127.0.0.1 - - [18/Apr/2021 20:36:11] "[31m[1mGET /upload HTTP/1.1[0m" 405 -
 * Detected change in '/home/slv/doSumn/script/app.py', reloading
 * Restarting with stat
 * Debugger is active!
 * Debugger PIN: 263-977-074
127.0.0.1 - - [18/Apr/2021 20:36:40] "[31m[1mGET /upload HTTP/1.1[0m" 405 -
127.0.0.1 - - [18/Apr/2021 20:36:44] "[37mGET /summary HTTP/1.1[0m" 200 -
127.0.0.1 - - [18/Apr/2021 20:36:48] "[37mPOST /upload HTTP/1.1[0m" 200 -
 * Detected change in '/home/slv/doSumn/script/app.py', reloading
 * Restarting with stat
 * Debugger is active!
 * Debugger PIN: 263-977-074
 * Detected change in '/home/slv/doSumn/script/app.py', reloading
 * Restarting with stat
 * Debugger is active!
 * Debugger PIN: 263-977-074
127.0.0.1 - - [18/Apr/2021 20:37:59] "[32mPOST /upload HTTP/1.1[0m" 302 -
127.0.0.1 - - [18/Apr/2021 20:37:59] "[31m[1mGET /upload HTTP/1.1[0m" 405 -
 * Detected change in '/home/slv/doSumn/script/app.py', reloading
 * Restarting with stat
 * Debugger is active!
 * Debugger PIN: 263-977-074
127.0.0.1 - - [18/Apr/2021 20:39:07] "[31m[1mGET /upload HTTP/1.1[0m" 405 -
127.0.0.1 - - [18/Apr/2021 20:39:09] "[31m[1mGET /upload HTTP/1.1[0m" 405 -
127.0.0.1 - - [18/Apr/2021 20:39:11] "[37mGET /summary HTTP/1.1[0m" 200 -
127.0.0.1 - - [18/Apr/2021 20:39:28] "[37mPOST /upload HTTP/1.1[0m" 200 -
 * Detected change in '/home/slv/doSumn/script/app.py', reloading
 * Restarting with stat
 * Debugger is active!
 * Debugger PIN: 263-977-074
127.0.0.1 - - [18/Apr/2021 20:42:56] "[37mPOST /upload HTTP/1.1[0m" 200 -
127.0.0.1 - - [18/Apr/2021 20:43:05] "[37mPOST /upload HTTP/1.1[0m" 200 -
127.0.0.1 - - [18/Apr/2021 20:43:10] "[37mPOST /upload HTTP/1.1[0m" 200 -
 * Detected change in '/home/slv/doSumn/script/app.py', reloading
 * Restarting with stat
 * Debugger is active!
 * Debugger PIN: 263-977-074
127.0.0.1 - - [18/Apr/2021 20:44:13] "[37mGET / HTTP/1.1[0m" 200 -
127.0.0.1 - - [18/Apr/2021 20:44:18] "[37mPOST /upload HTTP/1.1[0m" 200 -
 * Detected change in '/home/slv/doSumn/script/app.py', reloading
 * Restarting with stat
 * Debugger is active!
 * Debugger PIN: 263-977-074
 * Detected change in '/home/slv/doSumn/script/app.py', reloading
 * Restarting with stat
 * Debugger is active!
 * Debugger PIN: 263-977-074
127.0.0.1 - - [18/Apr/2021 20:47:24] "[37mGET / HTTP/1.1[0m" 200 -
127.0.0.1 - - [18/Apr/2021 20:47:28] "[37mPOST /upload HTTP/1.1[0m" 200 -
 * Detected change in '/home/slv/doSumn/script/app.py', reloading
 * Restarting with stat
 * Debugger is active!
 * Debugger PIN: 263-977-074
127.0.0.1 - - [18/Apr/2021 20:48:35] "[37mGET / HTTP/1.1[0m" 200 -
127.0.0.1 - - [18/Apr/2021 20:48:41] "[37mPOST /upload HTTP/1.1[0m" 200 -
 * Detected change in '/home/slv/doSumn/script/app.py', reloading
 * Restarting with stat
 * Debugger is active!
 * Debugger PIN: 263-977-074
image saved
127.0.0.1 - - [18/Apr/2021 20:49:04] "[37mPOST /upload HTTP/1.1[0m" 200 -
 * Detected change in '/home/slv/doSumn/script/app.py', reloading
 * Restarting with stat
 * Debugger is active!
 * Debugger PIN: 263-977-074
image saved
127.0.0.1 - - [18/Apr/2021 20:49:26] "[37mPOST /upload HTTP/1.1[0m" 200 -
 * Detected change in '/home/slv/doSumn/script/app.py', reloading
 * Restarting with stat
 * Debugger is active!
 * Debugger PIN: 263-977-074
image bodoh
127.0.0.1 - - [18/Apr/2021 20:49:56] "[37mPOST /upload HTTP/1.1[0m" 200 -
 * Detected change in '/home/slv/doSumn/script/app.py', reloading
 * Restarting with stat
 * Debugger is active!
 * Debugger PIN: 263-977-074
 * Detected change in '/home/slv/doSumn/script/app.py', reloading
 * Restarting with stat
 * Debugger is active!
 * Debugger PIN: 263-977-074
127.0.0.1 - - [18/Apr/2021 20:50:45] "[35m[1mPOST /upload HTTP/1.1[0m" 500 -
Traceback (most recent call last):
  File "/home/slv/.local/lib/python3.8/site-packages/flask/debughelpers.py", line 96, in __getitem__
    return oldcls.__getitem__(self, key)
  File "/home/slv/.local/lib/python3.8/site-packages/werkzeug/datastructures.py", line 442, in __getitem__
    raise exceptions.BadRequestKeyError(key)
werkzeug.exceptions.BadRequestKeyError: 400 Bad Request: The browser (or proxy) sent a request that this server could not understand.

During handling of the above exception, another exception occurred:

Traceback (most recent call last):
  File "/home/slv/.local/lib/python3.8/site-packages/flask/app.py", line 2464, in __call__
    return self.wsgi_app(environ, start_response)
  File "/home/slv/.local/lib/python3.8/site-packages/flask/app.py", line 2450, in wsgi_app
    response = self.handle_exception(e)
  File "/home/slv/.local/lib/python3.8/site-packages/flask/app.py", line 1867, in handle_exception
    reraise(exc_type, exc_value, tb)
  File "/home/slv/.local/lib/python3.8/site-packages/flask/_compat.py", line 39, in reraise
    raise value
  File "/home/slv/.local/lib/python3.8/site-packages/flask/app.py", line 2447, in wsgi_app
    response = self.full_dispatch_request()
  File "/home/slv/.local/lib/python3.8/site-packages/flask/app.py", line 1952, in full_dispatch_request
    rv = self.handle_user_exception(e)
  File "/home/slv/.local/lib/python3.8/site-packages/flask/app.py", line 1821, in handle_user_exception
    reraise(exc_type, exc_value, tb)
  File "/home/slv/.local/lib/python3.8/site-packages/flask/_compat.py", line 39, in reraise
    raise value
  File "/home/slv/.local/lib/python3.8/site-packages/flask/app.py", line 1950, in full_dispatch_request
    rv = self.dispatch_request()
  File "/home/slv/.local/lib/python3.8/site-packages/flask/app.py", line 1936, in dispatch_request
    return self.view_functions[rule.endpoint](**req.view_args)
  File "/home/slv/doSumn/script/app.py", line 15, in upload
    input = request.files['summ-in']
  File "/home/slv/.local/lib/python3.8/site-packages/flask/debughelpers.py", line 100, in __getitem__
    raise DebugFilesKeyError(request, key)
flask.debughelpers.DebugFilesKeyError: You tried to access the file "summ-in" in the request.files dictionary but it does not exist.  The mimetype for the request is "application/x-www-form-urlencoded" instead of "multipart/form-data" which means that no file contents were transmitted.  To fix this error you should provide enctype="multipart/form-data" in your form.

The browser instead transmitted some file names. This was submitted: "pos_neg.csv"
127.0.0.1 - - [18/Apr/2021 20:50:45] "[37mGET /upload?__debugger__=yes&cmd=resource&f=style.css HTTP/1.1[0m" 200 -
127.0.0.1 - - [18/Apr/2021 20:50:45] "[37mGET /upload?__debugger__=yes&cmd=resource&f=jquery.js HTTP/1.1[0m" 200 -
127.0.0.1 - - [18/Apr/2021 20:50:45] "[37mGET /upload?__debugger__=yes&cmd=resource&f=debugger.js HTTP/1.1[0m" 200 -
127.0.0.1 - - [18/Apr/2021 20:50:45] "[37mGET /upload?__debugger__=yes&cmd=resource&f=console.png HTTP/1.1[0m" 200 -
127.0.0.1 - - [18/Apr/2021 20:50:45] "[37mGET /upload?__debugger__=yes&cmd=resource&f=console.png HTTP/1.1[0m" 200 -
 * Detected change in '/home/slv/doSumn/script/app.py', reloading
 * Restarting with stat
 * Debugger is active!
 * Debugger PIN: 263-977-074
127.0.0.1 - - [18/Apr/2021 20:53:52] "[35m[1mPOST /upload HTTP/1.1[0m" 500 -
Traceback (most recent call last):
  File "/home/slv/.local/lib/python3.8/site-packages/flask/app.py", line 2464, in __call__
    return self.wsgi_app(environ, start_response)
  File "/home/slv/.local/lib/python3.8/site-packages/flask/app.py", line 2450, in wsgi_app
    response = self.handle_exception(e)
  File "/home/slv/.local/lib/python3.8/site-packages/flask/app.py", line 1867, in handle_exception
    reraise(exc_type, exc_value, tb)
  File "/home/slv/.local/lib/python3.8/site-packages/flask/_compat.py", line 39, in reraise
    raise value
  File "/home/slv/.local/lib/python3.8/site-packages/flask/app.py", line 2447, in wsgi_app
    response = self.full_dispatch_request()
  File "/home/slv/.local/lib/python3.8/site-packages/flask/app.py", line 1952, in full_dispatch_request
    rv = self.handle_user_exception(e)
  File "/home/slv/.local/lib/python3.8/site-packages/flask/app.py", line 1821, in handle_user_exception
    reraise(exc_type, exc_value, tb)
  File "/home/slv/.local/lib/python3.8/site-packages/flask/_compat.py", line 39, in reraise
    raise value
  File "/home/slv/.local/lib/python3.8/site-packages/flask/app.py", line 1950, in full_dispatch_request
    rv = self.dispatch_request()
  File "/home/slv/.local/lib/python3.8/site-packages/flask/app.py", line 1936, in dispatch_request
    return self.view_functions[rule.endpoint](**req.view_args)
  File "/home/slv/doSumn/script/app.py", line 15, in upload
    input = request.files[input]
UnboundLocalError: local variable 'input' referenced before assignment
127.0.0.1 - - [18/Apr/2021 20:53:52] "[37mGET /upload?__debugger__=yes&cmd=resource&f=style.css HTTP/1.1[0m" 200 -
127.0.0.1 - - [18/Apr/2021 20:53:52] "[37mGET /upload?__debugger__=yes&cmd=resource&f=jquery.js HTTP/1.1[0m" 200 -
127.0.0.1 - - [18/Apr/2021 20:53:52] "[37mGET /upload?__debugger__=yes&cmd=resource&f=debugger.js HTTP/1.1[0m" 200 -
127.0.0.1 - - [18/Apr/2021 20:53:52] "[37mGET /upload?__debugger__=yes&cmd=resource&f=console.png HTTP/1.1[0m" 200 -
127.0.0.1 - - [18/Apr/2021 20:53:52] "[37mGET /upload?__debugger__=yes&cmd=resource&f=console.png HTTP/1.1[0m" 200 -
 * Detected change in '/home/slv/doSumn/script/app.py', reloading
 * Restarting with stat
 * Debugger is active!
 * Debugger PIN: 263-977-074
127.0.0.1 - - [18/Apr/2021 20:54:07] "[35m[1mPOST /upload HTTP/1.1[0m" 500 -
Traceback (most recent call last):
  File "/home/slv/.local/lib/python3.8/site-packages/flask/app.py", line 2464, in __call__
    return self.wsgi_app(environ, start_response)
  File "/home/slv/.local/lib/python3.8/site-packages/flask/app.py", line 2450, in wsgi_app
    response = self.handle_exception(e)
  File "/home/slv/.local/lib/python3.8/site-packages/flask/app.py", line 1867, in handle_exception
    reraise(exc_type, exc_value, tb)
  File "/home/slv/.local/lib/python3.8/site-packages/flask/_compat.py", line 39, in reraise
    raise value
  File "/home/slv/.local/lib/python3.8/site-packages/flask/app.py", line 2447, in wsgi_app
    response = self.full_dispatch_request()
  File "/home/slv/.local/lib/python3.8/site-packages/flask/app.py", line 1952, in full_dispatch_request
    rv = self.handle_user_exception(e)
  File "/home/slv/.local/lib/python3.8/site-packages/flask/app.py", line 1821, in handle_user_exception
    reraise(exc_type, exc_value, tb)
  File "/home/slv/.local/lib/python3.8/site-packages/flask/_compat.py", line 39, in reraise
    raise value
  File "/home/slv/.local/lib/python3.8/site-packages/flask/app.py", line 1950, in full_dispatch_request
    rv = self.dispatch_request()
  File "/home/slv/.local/lib/python3.8/site-packages/flask/app.py", line 1936, in dispatch_request
    return self.view_functions[rule.endpoint](**req.view_args)
  File "/home/slv/doSumn/script/app.py", line 15, in upload
    input = request.files["input"]
  File "/home/slv/.local/lib/python3.8/site-packages/flask/debughelpers.py", line 96, in __getitem__
    return oldcls.__getitem__(self, key)
  File "/home/slv/.local/lib/python3.8/site-packages/werkzeug/datastructures.py", line 442, in __getitem__
    raise exceptions.BadRequestKeyError(key)
werkzeug.exceptions.BadRequestKeyError: 400 Bad Request: The browser (or proxy) sent a request that this server could not understand.
KeyError: 'input'
127.0.0.1 - - [18/Apr/2021 20:54:07] "[37mGET /upload?__debugger__=yes&cmd=resource&f=style.css HTTP/1.1[0m" 200 -
127.0.0.1 - - [18/Apr/2021 20:54:07] "[37mGET /upload?__debugger__=yes&cmd=resource&f=jquery.js HTTP/1.1[0m" 200 -
127.0.0.1 - - [18/Apr/2021 20:54:07] "[37mGET /upload?__debugger__=yes&cmd=resource&f=debugger.js HTTP/1.1[0m" 200 -
127.0.0.1 - - [18/Apr/2021 20:54:07] "[37mGET /upload?__debugger__=yes&cmd=resource&f=console.png HTTP/1.1[0m" 200 -
127.0.0.1 - - [18/Apr/2021 20:54:07] "[37mGET /upload?__debugger__=yes&cmd=resource&f=console.png HTTP/1.1[0m" 200 -
127.0.0.1 - - [18/Apr/2021 20:54:16] "[35m[1mPOST /upload HTTP/1.1[0m" 500 -
Traceback (most recent call last):
  File "/home/slv/.local/lib/python3.8/site-packages/flask/app.py", line 2464, in __call__
    return self.wsgi_app(environ, start_response)
  File "/home/slv/.local/lib/python3.8/site-packages/flask/app.py", line 2450, in wsgi_app
    response = self.handle_exception(e)
  File "/home/slv/.local/lib/python3.8/site-packages/flask/app.py", line 1867, in handle_exception
    reraise(exc_type, exc_value, tb)
  File "/home/slv/.local/lib/python3.8/site-packages/flask/_compat.py", line 39, in reraise
    raise value
  File "/home/slv/.local/lib/python3.8/site-packages/flask/app.py", line 2447, in wsgi_app
    response = self.full_dispatch_request()
  File "/home/slv/.local/lib/python3.8/site-packages/flask/app.py", line 1952, in full_dispatch_request
    rv = self.handle_user_exception(e)
  File "/home/slv/.local/lib/python3.8/site-packages/flask/app.py", line 1821, in handle_user_exception
    reraise(exc_type, exc_value, tb)
  File "/home/slv/.local/lib/python3.8/site-packages/flask/_compat.py", line 39, in reraise
    raise value
  File "/home/slv/.local/lib/python3.8/site-packages/flask/app.py", line 1950, in full_dispatch_request
    rv = self.dispatch_request()
  File "/home/slv/.local/lib/python3.8/site-packages/flask/app.py", line 1936, in dispatch_request
    return self.view_functions[rule.endpoint](**req.view_args)
  File "/home/slv/doSumn/script/app.py", line 15, in upload
    input = request.files["input"]
  File "/home/slv/.local/lib/python3.8/site-packages/flask/debughelpers.py", line 96, in __getitem__
    return oldcls.__getitem__(self, key)
  File "/home/slv/.local/lib/python3.8/site-packages/werkzeug/datastructures.py", line 442, in __getitem__
    raise exceptions.BadRequestKeyError(key)
werkzeug.exceptions.BadRequestKeyError: 400 Bad Request: The browser (or proxy) sent a request that this server could not understand.
KeyError: 'input'
127.0.0.1 - - [18/Apr/2021 20:54:16] "[37mGET /upload?__debugger__=yes&cmd=resource&f=style.css HTTP/1.1[0m" 200 -
127.0.0.1 - - [18/Apr/2021 20:54:16] "[37mGET /upload?__debugger__=yes&cmd=resource&f=debugger.js HTTP/1.1[0m" 200 -
127.0.0.1 - - [18/Apr/2021 20:54:16] "[37mGET /upload?__debugger__=yes&cmd=resource&f=jquery.js HTTP/1.1[0m" 200 -
127.0.0.1 - - [18/Apr/2021 20:54:16] "[37mGET /upload?__debugger__=yes&cmd=resource&f=console.png HTTP/1.1[0m" 200 -
127.0.0.1 - - [18/Apr/2021 20:54:16] "[37mGET /upload?__debugger__=yes&cmd=resource&f=console.png HTTP/1.1[0m" 200 -
 * Detected change in '/home/slv/doSumn/script/app.py', reloading
 * Restarting with stat
 * Debugger is active!
 * Debugger PIN: 263-977-074
127.0.0.1 - - [18/Apr/2021 20:55:29] "[35m[1mPOST /upload HTTP/1.1[0m" 500 -
Traceback (most recent call last):
  File "/home/slv/.local/lib/python3.8/site-packages/flask/app.py", line 2464, in __call__
    return self.wsgi_app(environ, start_response)
  File "/home/slv/.local/lib/python3.8/site-packages/flask/app.py", line 2450, in wsgi_app
    response = self.handle_exception(e)
  File "/home/slv/.local/lib/python3.8/site-packages/flask/app.py", line 1867, in handle_exception
    reraise(exc_type, exc_value, tb)
  File "/home/slv/.local/lib/python3.8/site-packages/flask/_compat.py", line 39, in reraise
    raise value
  File "/home/slv/.local/lib/python3.8/site-packages/flask/app.py", line 2447, in wsgi_app
    response = self.full_dispatch_request()
  File "/home/slv/.local/lib/python3.8/site-packages/flask/app.py", line 1952, in full_dispatch_request
    rv = self.handle_user_exception(e)
  File "/home/slv/.local/lib/python3.8/site-packages/flask/app.py", line 1821, in handle_user_exception
    reraise(exc_type, exc_value, tb)
  File "/home/slv/.local/lib/python3.8/site-packages/flask/_compat.py", line 39, in reraise
    raise value
  File "/home/slv/.local/lib/python3.8/site-packages/flask/app.py", line 1950, in full_dispatch_request
    rv = self.dispatch_request()
  File "/home/slv/.local/lib/python3.8/site-packages/flask/app.py", line 1936, in dispatch_request
    return self.view_functions[rule.endpoint](**req.view_args)
  File "/home/slv/doSumn/script/app.py", line 15, in upload
    input = request.files["input"]
  File "/home/slv/.local/lib/python3.8/site-packages/flask/debughelpers.py", line 96, in __getitem__
    return oldcls.__getitem__(self, key)
  File "/home/slv/.local/lib/python3.8/site-packages/werkzeug/datastructures.py", line 442, in __getitem__
    raise exceptions.BadRequestKeyError(key)
werkzeug.exceptions.BadRequestKeyError: 400 Bad Request: The browser (or proxy) sent a request that this server could not understand.
KeyError: 'input'
127.0.0.1 - - [18/Apr/2021 20:55:29] "[37mGET /upload?__debugger__=yes&cmd=resource&f=style.css HTTP/1.1[0m" 200 -
127.0.0.1 - - [18/Apr/2021 20:55:29] "[37mGET /upload?__debugger__=yes&cmd=resource&f=jquery.js HTTP/1.1[0m" 200 -
127.0.0.1 - - [18/Apr/2021 20:55:29] "[37mGET /upload?__debugger__=yes&cmd=resource&f=debugger.js HTTP/1.1[0m" 200 -
127.0.0.1 - - [18/Apr/2021 20:55:29] "[37mGET /upload?__debugger__=yes&cmd=resource&f=console.png HTTP/1.1[0m" 200 -
127.0.0.1 - - [18/Apr/2021 20:55:29] "[37mGET /upload?__debugger__=yes&cmd=resource&f=console.png HTTP/1.1[0m" 200 -
 * Detected change in '/home/slv/doSumn/script/app.py', reloading
 * Restarting with stat
 * Debugger is active!
 * Debugger PIN: 263-977-074
127.0.0.1 - - [18/Apr/2021 20:56:00] "[35m[1mPOST /upload HTTP/1.1[0m" 500 -
Traceback (most recent call last):
  File "/home/slv/.local/lib/python3.8/site-packages/flask/app.py", line 2464, in __call__
    return self.wsgi_app(environ, start_response)
  File "/home/slv/.local/lib/python3.8/site-packages/flask/app.py", line 2450, in wsgi_app
    response = self.handle_exception(e)
  File "/home/slv/.local/lib/python3.8/site-packages/flask/app.py", line 1867, in handle_exception
    reraise(exc_type, exc_value, tb)
  File "/home/slv/.local/lib/python3.8/site-packages/flask/_compat.py", line 39, in reraise
    raise value
  File "/home/slv/.local/lib/python3.8/site-packages/flask/app.py", line 2447, in wsgi_app
    response = self.full_dispatch_request()
  File "/home/slv/.local/lib/python3.8/site-packages/flask/app.py", line 1952, in full_dispatch_request
    rv = self.handle_user_exception(e)
  File "/home/slv/.local/lib/python3.8/site-packages/flask/app.py", line 1821, in handle_user_exception
    reraise(exc_type, exc_value, tb)
  File "/home/slv/.local/lib/python3.8/site-packages/flask/_compat.py", line 39, in reraise
    raise value
  File "/home/slv/.local/lib/python3.8/site-packages/flask/app.py", line 1950, in full_dispatch_request
    rv = self.dispatch_request()
  File "/home/slv/.local/lib/python3.8/site-packages/flask/app.py", line 1936, in dispatch_request
    return self.view_functions[rule.endpoint](**req.view_args)
  File "/home/slv/doSumn/script/app.py", line 15, in upload
    input = request.files['in-summ']
  File "/home/slv/.local/lib/python3.8/site-packages/flask/debughelpers.py", line 96, in __getitem__
    return oldcls.__getitem__(self, key)
  File "/home/slv/.local/lib/python3.8/site-packages/werkzeug/datastructures.py", line 442, in __getitem__
    raise exceptions.BadRequestKeyError(key)
werkzeug.exceptions.BadRequestKeyError: 400 Bad Request: The browser (or proxy) sent a request that this server could not understand.
KeyError: 'in-summ'
127.0.0.1 - - [18/Apr/2021 20:56:00] "[37mGET /upload?__debugger__=yes&cmd=resource&f=style.css HTTP/1.1[0m" 200 -
127.0.0.1 - - [18/Apr/2021 20:56:00] "[37mGET /upload?__debugger__=yes&cmd=resource&f=debugger.js HTTP/1.1[0m" 200 -
127.0.0.1 - - [18/Apr/2021 20:56:00] "[37mGET /upload?__debugger__=yes&cmd=resource&f=jquery.js HTTP/1.1[0m" 200 -
127.0.0.1 - - [18/Apr/2021 20:56:00] "[37mGET /upload?__debugger__=yes&cmd=resource&f=console.png HTTP/1.1[0m" 200 -
127.0.0.1 - - [18/Apr/2021 20:56:00] "[37mGET /upload?__debugger__=yes&cmd=resource&f=console.png HTTP/1.1[0m" 200 -
 * Detected change in '/home/slv/doSumn/script/app.py', reloading
 * Restarting with stat
 * Debugger is active!
 * Debugger PIN: 263-977-074
127.0.0.1 - - [18/Apr/2021 20:58:15] "[37mGET / HTTP/1.1[0m" 200 -
127.0.0.1 - - [18/Apr/2021 20:58:19] "[35m[1mPOST /upload HTTP/1.1[0m" 500 -
Traceback (most recent call last):
  File "/home/slv/.local/lib/python3.8/site-packages/flask/debughelpers.py", line 96, in __getitem__
    return oldcls.__getitem__(self, key)
  File "/home/slv/.local/lib/python3.8/site-packages/werkzeug/datastructures.py", line 442, in __getitem__
    raise exceptions.BadRequestKeyError(key)
werkzeug.exceptions.BadRequestKeyError: 400 Bad Request: The browser (or proxy) sent a request that this server could not understand.

During handling of the above exception, another exception occurred:

Traceback (most recent call last):
  File "/home/slv/.local/lib/python3.8/site-packages/flask/app.py", line 2464, in __call__
    return self.wsgi_app(environ, start_response)
  File "/home/slv/.local/lib/python3.8/site-packages/flask/app.py", line 2450, in wsgi_app
    response = self.handle_exception(e)
  File "/home/slv/.local/lib/python3.8/site-packages/flask/app.py", line 1867, in handle_exception
    reraise(exc_type, exc_value, tb)
  File "/home/slv/.local/lib/python3.8/site-packages/flask/_compat.py", line 39, in reraise
    raise value
  File "/home/slv/.local/lib/python3.8/site-packages/flask/app.py", line 2447, in wsgi_app
    response = self.full_dispatch_request()
  File "/home/slv/.local/lib/python3.8/site-packages/flask/app.py", line 1952, in full_dispatch_request
    rv = self.handle_user_exception(e)
  File "/home/slv/.local/lib/python3.8/site-packages/flask/app.py", line 1821, in handle_user_exception
    reraise(exc_type, exc_value, tb)
  File "/home/slv/.local/lib/python3.8/site-packages/flask/_compat.py", line 39, in reraise
    raise value
  File "/home/slv/.local/lib/python3.8/site-packages/flask/app.py", line 1950, in full_dispatch_request
    rv = self.dispatch_request()
  File "/home/slv/.local/lib/python3.8/site-packages/flask/app.py", line 1936, in dispatch_request
    return self.view_functions[rule.endpoint](**req.view_args)
  File "/home/slv/doSumn/script/app.py", line 15, in upload
    input = request.files['input']
  File "/home/slv/.local/lib/python3.8/site-packages/flask/debughelpers.py", line 100, in __getitem__
    raise DebugFilesKeyError(request, key)
flask.debughelpers.DebugFilesKeyError: You tried to access the file "input" in the request.files dictionary but it does not exist.  The mimetype for the request is "application/x-www-form-urlencoded" instead of "multipart/form-data" which means that no file contents were transmitted.  To fix this error you should provide enctype="multipart/form-data" in your form.

The browser instead transmitted some file names. This was submitted: "pos_neg.csv"
127.0.0.1 - - [18/Apr/2021 20:58:20] "[37mGET /upload?__debugger__=yes&cmd=resource&f=style.css HTTP/1.1[0m" 200 -
127.0.0.1 - - [18/Apr/2021 20:58:20] "[37mGET /upload?__debugger__=yes&cmd=resource&f=jquery.js HTTP/1.1[0m" 200 -
127.0.0.1 - - [18/Apr/2021 20:58:20] "[37mGET /upload?__debugger__=yes&cmd=resource&f=debugger.js HTTP/1.1[0m" 200 -
127.0.0.1 - - [18/Apr/2021 20:58:20] "[37mGET /upload?__debugger__=yes&cmd=resource&f=console.png HTTP/1.1[0m" 200 -
127.0.0.1 - - [18/Apr/2021 21:01:19] "[37mGET / HTTP/1.1[0m" 200 -
<FileStorage: 'dataset.csv' ('text/csv')>
127.0.0.1 - - [18/Apr/2021 21:01:23] "[32mPOST /upload HTTP/1.1[0m" 302 -
127.0.0.1 - - [18/Apr/2021 21:01:23] "[37mGET /upload HTTP/1.1[0m" 200 -
 * Detected change in '/home/slv/doSumn/script/app.py', reloading
 * Restarting with stat
 * Debugger is active!
 * Debugger PIN: 263-977-074
<FileStorage: 'dataset.csv' ('text/csv')>
127.0.0.1 - - [18/Apr/2021 21:30:31] "[35m[1mPOST /upload HTTP/1.1[0m" 500 -
Traceback (most recent call last):
  File "/usr/lib/python3.8/posixpath.py", line 82, in join
    for b in map(os.fspath, p):
TypeError: expected str, bytes or os.PathLike object, not FileStorage

During handling of the above exception, another exception occurred:

Traceback (most recent call last):
  File "/home/slv/.local/lib/python3.8/site-packages/flask/app.py", line 2464, in __call__
    return self.wsgi_app(environ, start_response)
  File "/home/slv/.local/lib/python3.8/site-packages/flask/app.py", line 2450, in wsgi_app
    response = self.handle_exception(e)
  File "/home/slv/.local/lib/python3.8/site-packages/flask/app.py", line 1867, in handle_exception
    reraise(exc_type, exc_value, tb)
  File "/home/slv/.local/lib/python3.8/site-packages/flask/_compat.py", line 39, in reraise
    raise value
  File "/home/slv/.local/lib/python3.8/site-packages/flask/app.py", line 2447, in wsgi_app
    response = self.full_dispatch_request()
  File "/home/slv/.local/lib/python3.8/site-packages/flask/app.py", line 1952, in full_dispatch_request
    rv = self.handle_user_exception(e)
  File "/home/slv/.local/lib/python3.8/site-packages/flask/app.py", line 1821, in handle_user_exception
    reraise(exc_type, exc_value, tb)
  File "/home/slv/.local/lib/python3.8/site-packages/flask/_compat.py", line 39, in reraise
    raise value
  File "/home/slv/.local/lib/python3.8/site-packages/flask/app.py", line 1950, in full_dispatch_request
    rv = self.dispatch_request()
  File "/home/slv/.local/lib/python3.8/site-packages/flask/app.py", line 1936, in dispatch_request
    return self.view_functions[rule.endpoint](**req.view_args)
  File "/home/slv/doSumn/script/app.py", line 17, in upload
    input.save(os.path.join(app.config['UPLOAD_FOLDER'], input))
  File "/usr/lib/python3.8/posixpath.py", line 90, in join
    genericpath._check_arg_types('join', a, *p)
  File "/usr/lib/python3.8/genericpath.py", line 152, in _check_arg_types
    raise TypeError(f'{funcname}() argument must be str, bytes, or '
TypeError: join() argument must be str, bytes, or os.PathLike object, not 'FileStorage'
127.0.0.1 - - [18/Apr/2021 21:30:31] "[37mGET /upload?__debugger__=yes&cmd=resource&f=debugger.js HTTP/1.1[0m" 200 -
127.0.0.1 - - [18/Apr/2021 21:30:31] "[37mGET /upload?__debugger__=yes&cmd=resource&f=style.css HTTP/1.1[0m" 200 -
127.0.0.1 - - [18/Apr/2021 21:30:31] "[37mGET /upload?__debugger__=yes&cmd=resource&f=jquery.js HTTP/1.1[0m" 200 -
127.0.0.1 - - [18/Apr/2021 21:30:31] "[37mGET /upload?__debugger__=yes&cmd=resource&f=console.png HTTP/1.1[0m" 200 -
127.0.0.1 - - [18/Apr/2021 21:30:31] "[37mGET /upload?__debugger__=yes&cmd=resource&f=console.png HTTP/1.1[0m" 200 -
 * Detected change in '/home/slv/doSumn/script/app.py', reloading
 * Restarting with stat
 * Debugger is active!
 * Debugger PIN: 263-977-074
<FileStorage: 'dataset.csv' ('text/csv')>
127.0.0.1 - - [18/Apr/2021 21:33:50] "[35m[1mPOST /upload HTTP/1.1[0m" 500 -
Traceback (most recent call last):
  File "/usr/lib/python3.8/posixpath.py", line 82, in join
    for b in map(os.fspath, p):
TypeError: expected str, bytes or os.PathLike object, not FileStorage

During handling of the above exception, another exception occurred:

Traceback (most recent call last):
  File "/home/slv/.local/lib/python3.8/site-packages/flask/app.py", line 2464, in __call__
    return self.wsgi_app(environ, start_response)
  File "/home/slv/.local/lib/python3.8/site-packages/flask/app.py", line 2450, in wsgi_app
    response = self.handle_exception(e)
  File "/home/slv/.local/lib/python3.8/site-packages/flask/app.py", line 1867, in handle_exception
    reraise(exc_type, exc_value, tb)
  File "/home/slv/.local/lib/python3.8/site-packages/flask/_compat.py", line 39, in reraise
    raise value
  File "/home/slv/.local/lib/python3.8/site-packages/flask/app.py", line 2447, in wsgi_app
    response = self.full_dispatch_request()
  File "/home/slv/.local/lib/python3.8/site-packages/flask/app.py", line 1952, in full_dispatch_request
    rv = self.handle_user_exception(e)
  File "/home/slv/.local/lib/python3.8/site-packages/flask/app.py", line 1821, in handle_user_exception
    reraise(exc_type, exc_value, tb)
  File "/home/slv/.local/lib/python3.8/site-packages/flask/_compat.py", line 39, in reraise
    raise value
  File "/home/slv/.local/lib/python3.8/site-packages/flask/app.py", line 1950, in full_dispatch_request
    rv = self.dispatch_request()
  File "/home/slv/.local/lib/python3.8/site-packages/flask/app.py", line 1936, in dispatch_request
    return self.view_functions[rule.endpoint](**req.view_args)
  File "/home/slv/doSumn/script/app.py", line 17, in upload
    input.save(os.path.join(app.config['UPLOAD_FOLDER'], input))
  File "/usr/lib/python3.8/posixpath.py", line 90, in join
    genericpath._check_arg_types('join', a, *p)
  File "/usr/lib/python3.8/genericpath.py", line 152, in _check_arg_types
    raise TypeError(f'{funcname}() argument must be str, bytes, or '
TypeError: join() argument must be str, bytes, or os.PathLike object, not 'FileStorage'
127.0.0.1 - - [18/Apr/2021 21:33:50] "[37mGET /upload?__debugger__=yes&cmd=resource&f=style.css HTTP/1.1[0m" 200 -
127.0.0.1 - - [18/Apr/2021 21:33:50] "[37mGET /upload?__debugger__=yes&cmd=resource&f=debugger.js HTTP/1.1[0m" 200 -
127.0.0.1 - - [18/Apr/2021 21:33:50] "[37mGET /upload?__debugger__=yes&cmd=resource&f=jquery.js HTTP/1.1[0m" 200 -
127.0.0.1 - - [18/Apr/2021 21:33:50] "[37mGET /upload?__debugger__=yes&cmd=resource&f=console.png HTTP/1.1[0m" 200 -
127.0.0.1 - - [18/Apr/2021 21:33:50] "[37mGET /upload?__debugger__=yes&cmd=resource&f=console.png HTTP/1.1[0m" 200 -
 * Detected change in '/home/slv/doSumn/script/app.py', reloading
 * Restarting with stat
 * Debugger is active!
 * Debugger PIN: 263-977-074
127.0.0.1 - - [18/Apr/2021 21:36:01] "[37mGET /upload HTTP/1.1[0m" 200 -
<FileStorage: 'dataset.csv' ('text/csv')>
127.0.0.1 - - [18/Apr/2021 21:36:06] "[35m[1mPOST /upload HTTP/1.1[0m" 500 -
Traceback (most recent call last):
  File "/home/slv/.local/lib/python3.8/site-packages/flask/app.py", line 2464, in __call__
    return self.wsgi_app(environ, start_response)
  File "/home/slv/.local/lib/python3.8/site-packages/flask/app.py", line 2450, in wsgi_app
    response = self.handle_exception(e)
  File "/home/slv/.local/lib/python3.8/site-packages/flask/app.py", line 1867, in handle_exception
    reraise(exc_type, exc_value, tb)
  File "/home/slv/.local/lib/python3.8/site-packages/flask/_compat.py", line 39, in reraise
    raise value
  File "/home/slv/.local/lib/python3.8/site-packages/flask/app.py", line 2447, in wsgi_app
    response = self.full_dispatch_request()
  File "/home/slv/.local/lib/python3.8/site-packages/flask/app.py", line 1952, in full_dispatch_request
    rv = self.handle_user_exception(e)
  File "/home/slv/.local/lib/python3.8/site-packages/flask/app.py", line 1821, in handle_user_exception
    reraise(exc_type, exc_value, tb)
  File "/home/slv/.local/lib/python3.8/site-packages/flask/_compat.py", line 39, in reraise
    raise value
  File "/home/slv/.local/lib/python3.8/site-packages/flask/app.py", line 1950, in full_dispatch_request
    rv = self.dispatch_request()
  File "/home/slv/.local/lib/python3.8/site-packages/flask/app.py", line 1936, in dispatch_request
    return self.view_functions[rule.endpoint](**req.view_args)
  File "/home/slv/doSumn/script/app.py", line 17, in upload
    input.save(os.path.join(app.config['UPLOAD_FOLDER'], "t.csv"))
  File "/home/slv/.local/lib/python3.8/site-packages/werkzeug/datastructures.py", line 3066, in save
    dst = open(dst, "wb")
FileNotFoundError: [Errno 2] No such file or directory: '/home/slv/doSumn/uploads/t.csv'
127.0.0.1 - - [18/Apr/2021 21:36:06] "[37mGET /upload?__debugger__=yes&cmd=resource&f=style.css HTTP/1.1[0m" 200 -
127.0.0.1 - - [18/Apr/2021 21:36:06] "[37mGET /upload?__debugger__=yes&cmd=resource&f=debugger.js HTTP/1.1[0m" 200 -
127.0.0.1 - - [18/Apr/2021 21:36:06] "[37mGET /upload?__debugger__=yes&cmd=resource&f=jquery.js HTTP/1.1[0m" 200 -
127.0.0.1 - - [18/Apr/2021 21:36:06] "[37mGET /upload?__debugger__=yes&cmd=resource&f=console.png HTTP/1.1[0m" 200 -
127.0.0.1 - - [18/Apr/2021 21:36:06] "[37mGET /upload?__debugger__=yes&cmd=resource&f=console.png HTTP/1.1[0m" 200 -
 * Detected change in '/home/slv/doSumn/script/app.py', reloading
 * Restarting with stat
 * Debugger is active!
 * Debugger PIN: 263-977-074
 * Detected change in '/home/slv/doSumn/script/app.py', reloading
 * Restarting with stat
 * Debugger is active!
 * Debugger PIN: 263-977-074
127.0.0.1 - - [18/Apr/2021 21:37:11] "[37mGET /upload HTTP/1.1[0m" 200 -
<FileStorage: 'dataset.csv' ('text/csv')>
127.0.0.1 - - [18/Apr/2021 21:37:15] "[35m[1mPOST /upload HTTP/1.1[0m" 500 -
Traceback (most recent call last):
  File "/home/slv/.local/lib/python3.8/site-packages/flask/app.py", line 2464, in __call__
    return self.wsgi_app(environ, start_response)
  File "/home/slv/.local/lib/python3.8/site-packages/flask/app.py", line 2450, in wsgi_app
    response = self.handle_exception(e)
  File "/home/slv/.local/lib/python3.8/site-packages/flask/app.py", line 1867, in handle_exception
    reraise(exc_type, exc_value, tb)
  File "/home/slv/.local/lib/python3.8/site-packages/flask/_compat.py", line 39, in reraise
    raise value
  File "/home/slv/.local/lib/python3.8/site-packages/flask/app.py", line 2447, in wsgi_app
    response = self.full_dispatch_request()
  File "/home/slv/.local/lib/python3.8/site-packages/flask/app.py", line 1952, in full_dispatch_request
    rv = self.handle_user_exception(e)
  File "/home/slv/.local/lib/python3.8/site-packages/flask/app.py", line 1821, in handle_user_exception
    reraise(exc_type, exc_value, tb)
  File "/home/slv/.local/lib/python3.8/site-packages/flask/_compat.py", line 39, in reraise
    raise value
  File "/home/slv/.local/lib/python3.8/site-packages/flask/app.py", line 1950, in full_dispatch_request
    rv = self.dispatch_request()
  File "/home/slv/.local/lib/python3.8/site-packages/flask/app.py", line 1936, in dispatch_request
    return self.view_functions[rule.endpoint](**req.view_args)
  File "/home/slv/doSumn/script/app.py", line 17, in upload
    input.save(os.path.join(app.config['UPLOAD_FOLDER'], input.filename))
  File "/home/slv/.local/lib/python3.8/site-packages/werkzeug/datastructures.py", line 3066, in save
    dst = open(dst, "wb")
FileNotFoundError: [Errno 2] No such file or directory: '/uploads/dataset.csv'
127.0.0.1 - - [18/Apr/2021 21:37:15] "[37mGET /upload?__debugger__=yes&cmd=resource&f=style.css HTTP/1.1[0m" 200 -
127.0.0.1 - - [18/Apr/2021 21:37:15] "[37mGET /upload?__debugger__=yes&cmd=resource&f=jquery.js HTTP/1.1[0m" 200 -
127.0.0.1 - - [18/Apr/2021 21:37:15] "[37mGET /upload?__debugger__=yes&cmd=resource&f=debugger.js HTTP/1.1[0m" 200 -
127.0.0.1 - - [18/Apr/2021 21:37:15] "[37mGET /upload?__debugger__=yes&cmd=resource&f=console.png HTTP/1.1[0m" 200 -
127.0.0.1 - - [18/Apr/2021 21:37:16] "[37mGET /upload?__debugger__=yes&cmd=resource&f=console.png HTTP/1.1[0m" 200 -
127.0.0.1 - - [18/Apr/2021 21:37:29] "[37mGET /upload?__debugger__=yes&cmd=resource&f=style.css HTTP/1.1[0m" 200 -
 * Detected change in '/home/slv/doSumn/script/app.py', reloading
 * Restarting with stat
 * Debugger is active!
 * Debugger PIN: 263-977-074
127.0.0.1 - - [18/Apr/2021 21:40:14] "[37mGET /upload HTTP/1.1[0m" 200 -
<FileStorage: 'pos_neg.csv' ('text/csv')>
127.0.0.1 - - [18/Apr/2021 21:40:20] "[35m[1mPOST /upload HTTP/1.1[0m" 500 -
Traceback (most recent call last):
  File "/home/slv/.local/lib/python3.8/site-packages/flask/app.py", line 2464, in __call__
    return self.wsgi_app(environ, start_response)
  File "/home/slv/.local/lib/python3.8/site-packages/flask/app.py", line 2450, in wsgi_app
    response = self.handle_exception(e)
  File "/home/slv/.local/lib/python3.8/site-packages/flask/app.py", line 1867, in handle_exception
    reraise(exc_type, exc_value, tb)
  File "/home/slv/.local/lib/python3.8/site-packages/flask/_compat.py", line 39, in reraise
    raise value
  File "/home/slv/.local/lib/python3.8/site-packages/flask/app.py", line 2447, in wsgi_app
    response = self.full_dispatch_request()
  File "/home/slv/.local/lib/python3.8/site-packages/flask/app.py", line 1952, in full_dispatch_request
    rv = self.handle_user_exception(e)
  File "/home/slv/.local/lib/python3.8/site-packages/flask/app.py", line 1821, in handle_user_exception
    reraise(exc_type, exc_value, tb)
  File "/home/slv/.local/lib/python3.8/site-packages/flask/_compat.py", line 39, in reraise
    raise value
  File "/home/slv/.local/lib/python3.8/site-packages/flask/app.py", line 1950, in full_dispatch_request
    rv = self.dispatch_request()
  File "/home/slv/.local/lib/python3.8/site-packages/flask/app.py", line 1936, in dispatch_request
    return self.view_functions[rule.endpoint](**req.view_args)
  File "/home/slv/doSumn/script/app.py", line 17, in upload
    input.save(os.path.join(app.config['UPLOAD_PATH'], input.filename))
  File "/home/slv/.local/lib/python3.8/site-packages/werkzeug/datastructures.py", line 3066, in save
    dst = open(dst, "wb")
FileNotFoundError: [Errno 2] No such file or directory: '/uploads/pos_neg.csv'
127.0.0.1 - - [18/Apr/2021 21:40:20] "[37mGET /upload?__debugger__=yes&cmd=resource&f=style.css HTTP/1.1[0m" 200 -
127.0.0.1 - - [18/Apr/2021 21:40:20] "[37mGET /upload?__debugger__=yes&cmd=resource&f=jquery.js HTTP/1.1[0m" 200 -
127.0.0.1 - - [18/Apr/2021 21:40:20] "[37mGET /upload?__debugger__=yes&cmd=resource&f=debugger.js HTTP/1.1[0m" 200 -
127.0.0.1 - - [18/Apr/2021 21:40:20] "[37mGET /upload?__debugger__=yes&cmd=resource&f=console.png HTTP/1.1[0m" 200 -
127.0.0.1 - - [18/Apr/2021 21:40:20] "[37mGET /upload?__debugger__=yes&cmd=resource&f=console.png HTTP/1.1[0m" 200 -
<FileStorage: 'pos_neg.csv' ('text/csv')>
127.0.0.1 - - [18/Apr/2021 21:41:15] "[35m[1mPOST /upload HTTP/1.1[0m" 500 -
Traceback (most recent call last):
  File "/home/slv/.local/lib/python3.8/site-packages/flask/app.py", line 2464, in __call__
    return self.wsgi_app(environ, start_response)
  File "/home/slv/.local/lib/python3.8/site-packages/flask/app.py", line 2450, in wsgi_app
    response = self.handle_exception(e)
  File "/home/slv/.local/lib/python3.8/site-packages/flask/app.py", line 1867, in handle_exception
    reraise(exc_type, exc_value, tb)
  File "/home/slv/.local/lib/python3.8/site-packages/flask/_compat.py", line 39, in reraise
    raise value
  File "/home/slv/.local/lib/python3.8/site-packages/flask/app.py", line 2447, in wsgi_app
    response = self.full_dispatch_request()
  File "/home/slv/.local/lib/python3.8/site-packages/flask/app.py", line 1952, in full_dispatch_request
    rv = self.handle_user_exception(e)
  File "/home/slv/.local/lib/python3.8/site-packages/flask/app.py", line 1821, in handle_user_exception
    reraise(exc_type, exc_value, tb)
  File "/home/slv/.local/lib/python3.8/site-packages/flask/_compat.py", line 39, in reraise
    raise value
  File "/home/slv/.local/lib/python3.8/site-packages/flask/app.py", line 1950, in full_dispatch_request
    rv = self.dispatch_request()
  File "/home/slv/.local/lib/python3.8/site-packages/flask/app.py", line 1936, in dispatch_request
    return self.view_functions[rule.endpoint](**req.view_args)
  File "/home/slv/doSumn/script/app.py", line 17, in upload
    input.save(os.path.join(app.config['UPLOAD_PATH'], input.filename))
  File "/home/slv/.local/lib/python3.8/site-packages/werkzeug/datastructures.py", line 3066, in save
    dst = open(dst, "wb")
FileNotFoundError: [Errno 2] No such file or directory: '/uploads/pos_neg.csv'
127.0.0.1 - - [18/Apr/2021 21:41:15] "[37mGET /upload?__debugger__=yes&cmd=resource&f=style.css HTTP/1.1[0m" 200 -
127.0.0.1 - - [18/Apr/2021 21:41:15] "[37mGET /upload?__debugger__=yes&cmd=resource&f=debugger.js HTTP/1.1[0m" 200 -
127.0.0.1 - - [18/Apr/2021 21:41:15] "[37mGET /upload?__debugger__=yes&cmd=resource&f=jquery.js HTTP/1.1[0m" 200 -
127.0.0.1 - - [18/Apr/2021 21:41:16] "[37mGET /upload?__debugger__=yes&cmd=resource&f=console.png HTTP/1.1[0m" 200 -
127.0.0.1 - - [18/Apr/2021 21:41:16] "[37mGET /upload?__debugger__=yes&cmd=resource&f=console.png HTTP/1.1[0m" 200 -
127.0.0.1 - - [18/Apr/2021 21:41:20] "[37mGET /upload HTTP/1.1[0m" 200 -
<FileStorage: 'pos_neg.csv' ('text/csv')>
127.0.0.1 - - [18/Apr/2021 21:41:24] "[35m[1mPOST /upload HTTP/1.1[0m" 500 -
Traceback (most recent call last):
  File "/home/slv/.local/lib/python3.8/site-packages/flask/app.py", line 2464, in __call__
    return self.wsgi_app(environ, start_response)
  File "/home/slv/.local/lib/python3.8/site-packages/flask/app.py", line 2450, in wsgi_app
    response = self.handle_exception(e)
  File "/home/slv/.local/lib/python3.8/site-packages/flask/app.py", line 1867, in handle_exception
    reraise(exc_type, exc_value, tb)
  File "/home/slv/.local/lib/python3.8/site-packages/flask/_compat.py", line 39, in reraise
    raise value
  File "/home/slv/.local/lib/python3.8/site-packages/flask/app.py", line 2447, in wsgi_app
    response = self.full_dispatch_request()
  File "/home/slv/.local/lib/python3.8/site-packages/flask/app.py", line 1952, in full_dispatch_request
    rv = self.handle_user_exception(e)
  File "/home/slv/.local/lib/python3.8/site-packages/flask/app.py", line 1821, in handle_user_exception
    reraise(exc_type, exc_value, tb)
  File "/home/slv/.local/lib/python3.8/site-packages/flask/_compat.py", line 39, in reraise
    raise value
  File "/home/slv/.local/lib/python3.8/site-packages/flask/app.py", line 1950, in full_dispatch_request
    rv = self.dispatch_request()
  File "/home/slv/.local/lib/python3.8/site-packages/flask/app.py", line 1936, in dispatch_request
    return self.view_functions[rule.endpoint](**req.view_args)
  File "/home/slv/doSumn/script/app.py", line 17, in upload
    input.save(os.path.join(app.config['UPLOAD_PATH'], input.filename))
  File "/home/slv/.local/lib/python3.8/site-packages/werkzeug/datastructures.py", line 3066, in save
    dst = open(dst, "wb")
FileNotFoundError: [Errno 2] No such file or directory: '/uploads/pos_neg.csv'
127.0.0.1 - - [18/Apr/2021 21:41:24] "[37mGET /upload?__debugger__=yes&cmd=resource&f=style.css HTTP/1.1[0m" 200 -
127.0.0.1 - - [18/Apr/2021 21:41:24] "[37mGET /upload?__debugger__=yes&cmd=resource&f=jquery.js HTTP/1.1[0m" 200 -
127.0.0.1 - - [18/Apr/2021 21:41:24] "[37mGET /upload?__debugger__=yes&cmd=resource&f=debugger.js HTTP/1.1[0m" 200 -
127.0.0.1 - - [18/Apr/2021 21:41:24] "[37mGET /upload?__debugger__=yes&cmd=resource&f=console.png HTTP/1.1[0m" 200 -
127.0.0.1 - - [18/Apr/2021 21:41:24] "[37mGET /upload?__debugger__=yes&cmd=resource&f=console.png HTTP/1.1[0m" 200 -
127.0.0.1 - - [18/Apr/2021 21:41:42] "[37mGET /upload HTTP/1.1[0m" 200 -
<FileStorage: 'pos_neg.csv' ('text/csv')>
127.0.0.1 - - [18/Apr/2021 21:41:46] "[35m[1mPOST /upload HTTP/1.1[0m" 500 -
Traceback (most recent call last):
  File "/home/slv/.local/lib/python3.8/site-packages/flask/app.py", line 2464, in __call__
    return self.wsgi_app(environ, start_response)
  File "/home/slv/.local/lib/python3.8/site-packages/flask/app.py", line 2450, in wsgi_app
    response = self.handle_exception(e)
  File "/home/slv/.local/lib/python3.8/site-packages/flask/app.py", line 1867, in handle_exception
    reraise(exc_type, exc_value, tb)
  File "/home/slv/.local/lib/python3.8/site-packages/flask/_compat.py", line 39, in reraise
    raise value
  File "/home/slv/.local/lib/python3.8/site-packages/flask/app.py", line 2447, in wsgi_app
    response = self.full_dispatch_request()
  File "/home/slv/.local/lib/python3.8/site-packages/flask/app.py", line 1952, in full_dispatch_request
    rv = self.handle_user_exception(e)
  File "/home/slv/.local/lib/python3.8/site-packages/flask/app.py", line 1821, in handle_user_exception
    reraise(exc_type, exc_value, tb)
  File "/home/slv/.local/lib/python3.8/site-packages/flask/_compat.py", line 39, in reraise
    raise value
  File "/home/slv/.local/lib/python3.8/site-packages/flask/app.py", line 1950, in full_dispatch_request
    rv = self.dispatch_request()
  File "/home/slv/.local/lib/python3.8/site-packages/flask/app.py", line 1936, in dispatch_request
    return self.view_functions[rule.endpoint](**req.view_args)
  File "/home/slv/doSumn/script/app.py", line 17, in upload
    input.save(os.path.join(app.config['UPLOAD_PATH'], input.filename))
  File "/home/slv/.local/lib/python3.8/site-packages/werkzeug/datastructures.py", line 3066, in save
    dst = open(dst, "wb")
FileNotFoundError: [Errno 2] No such file or directory: '/uploads/pos_neg.csv'
127.0.0.1 - - [18/Apr/2021 21:41:46] "[37mGET /upload?__debugger__=yes&cmd=resource&f=style.css HTTP/1.1[0m" 200 -
127.0.0.1 - - [18/Apr/2021 21:41:46] "[37mGET /upload?__debugger__=yes&cmd=resource&f=jquery.js HTTP/1.1[0m" 200 -
127.0.0.1 - - [18/Apr/2021 21:41:46] "[37mGET /upload?__debugger__=yes&cmd=resource&f=debugger.js HTTP/1.1[0m" 200 -
127.0.0.1 - - [18/Apr/2021 21:41:46] "[37mGET /upload?__debugger__=yes&cmd=resource&f=console.png HTTP/1.1[0m" 200 -
127.0.0.1 - - [18/Apr/2021 21:41:46] "[37mGET /upload?__debugger__=yes&cmd=resource&f=console.png HTTP/1.1[0m" 200 -
 * Detected change in '/home/slv/doSumn/script/app.py', reloading
 * Restarting with stat
 * Debugger is active!
 * Debugger PIN: 263-977-074
<FileStorage: 'dataset.csv' ('text/csv')>
127.0.0.1 - - [18/Apr/2021 21:42:11] "[35m[1mPOST /upload HTTP/1.1[0m" 500 -
Traceback (most recent call last):
  File "/home/slv/.local/lib/python3.8/site-packages/flask/app.py", line 2464, in __call__
    return self.wsgi_app(environ, start_response)
  File "/home/slv/.local/lib/python3.8/site-packages/flask/app.py", line 2450, in wsgi_app
    response = self.handle_exception(e)
  File "/home/slv/.local/lib/python3.8/site-packages/flask/app.py", line 1867, in handle_exception
    reraise(exc_type, exc_value, tb)
  File "/home/slv/.local/lib/python3.8/site-packages/flask/_compat.py", line 39, in reraise
    raise value
  File "/home/slv/.local/lib/python3.8/site-packages/flask/app.py", line 2447, in wsgi_app
    response = self.full_dispatch_request()
  File "/home/slv/.local/lib/python3.8/site-packages/flask/app.py", line 1952, in full_dispatch_request
    rv = self.handle_user_exception(e)
  File "/home/slv/.local/lib/python3.8/site-packages/flask/app.py", line 1821, in handle_user_exception
    reraise(exc_type, exc_value, tb)
  File "/home/slv/.local/lib/python3.8/site-packages/flask/_compat.py", line 39, in reraise
    raise value
  File "/home/slv/.local/lib/python3.8/site-packages/flask/app.py", line 1950, in full_dispatch_request
    rv = self.dispatch_request()
  File "/home/slv/.local/lib/python3.8/site-packages/flask/app.py", line 1936, in dispatch_request
    return self.view_functions[rule.endpoint](**req.view_args)
  File "/home/slv/doSumn/script/app.py", line 17, in upload
    input.save(os.path.join(app.config['UPLOAD_PATH'], input.filename))
  File "/home/slv/.local/lib/python3.8/site-packages/werkzeug/datastructures.py", line 3066, in save
    dst = open(dst, "wb")
FileNotFoundError: [Errno 2] No such file or directory: 'uploads/dataset.csv'
127.0.0.1 - - [18/Apr/2021 21:42:11] "[37mGET /upload?__debugger__=yes&cmd=resource&f=style.css HTTP/1.1[0m" 200 -
127.0.0.1 - - [18/Apr/2021 21:42:11] "[37mGET /upload?__debugger__=yes&cmd=resource&f=jquery.js HTTP/1.1[0m" 200 -
127.0.0.1 - - [18/Apr/2021 21:42:11] "[37mGET /upload?__debugger__=yes&cmd=resource&f=debugger.js HTTP/1.1[0m" 200 -
127.0.0.1 - - [18/Apr/2021 21:42:11] "[37mGET /upload?__debugger__=yes&cmd=resource&f=console.png HTTP/1.1[0m" 200 -
127.0.0.1 - - [18/Apr/2021 21:42:11] "[37mGET /upload?__debugger__=yes&cmd=resource&f=console.png HTTP/1.1[0m" 200 -
127.0.0.1 - - [18/Apr/2021 21:42:17] "[37mGET /upload HTTP/1.1[0m" 200 -
<FileStorage: 'dataset.csv' ('text/csv')>
127.0.0.1 - - [18/Apr/2021 21:42:22] "[35m[1mPOST /upload HTTP/1.1[0m" 500 -
Traceback (most recent call last):
  File "/home/slv/.local/lib/python3.8/site-packages/flask/app.py", line 2464, in __call__
    return self.wsgi_app(environ, start_response)
  File "/home/slv/.local/lib/python3.8/site-packages/flask/app.py", line 2450, in wsgi_app
    response = self.handle_exception(e)
  File "/home/slv/.local/lib/python3.8/site-packages/flask/app.py", line 1867, in handle_exception
    reraise(exc_type, exc_value, tb)
  File "/home/slv/.local/lib/python3.8/site-packages/flask/_compat.py", line 39, in reraise
    raise value
  File "/home/slv/.local/lib/python3.8/site-packages/flask/app.py", line 2447, in wsgi_app
    response = self.full_dispatch_request()
  File "/home/slv/.local/lib/python3.8/site-packages/flask/app.py", line 1952, in full_dispatch_request
    rv = self.handle_user_exception(e)
  File "/home/slv/.local/lib/python3.8/site-packages/flask/app.py", line 1821, in handle_user_exception
    reraise(exc_type, exc_value, tb)
  File "/home/slv/.local/lib/python3.8/site-packages/flask/_compat.py", line 39, in reraise
    raise value
  File "/home/slv/.local/lib/python3.8/site-packages/flask/app.py", line 1950, in full_dispatch_request
    rv = self.dispatch_request()
  File "/home/slv/.local/lib/python3.8/site-packages/flask/app.py", line 1936, in dispatch_request
    return self.view_functions[rule.endpoint](**req.view_args)
  File "/home/slv/doSumn/script/app.py", line 17, in upload
    input.save(os.path.join(app.config['UPLOAD_PATH'], input.filename))
  File "/home/slv/.local/lib/python3.8/site-packages/werkzeug/datastructures.py", line 3066, in save
    dst = open(dst, "wb")
FileNotFoundError: [Errno 2] No such file or directory: 'uploads/dataset.csv'
127.0.0.1 - - [18/Apr/2021 21:42:22] "[37mGET /upload?__debugger__=yes&cmd=resource&f=style.css HTTP/1.1[0m" 200 -
127.0.0.1 - - [18/Apr/2021 21:42:22] "[37mGET /upload?__debugger__=yes&cmd=resource&f=jquery.js HTTP/1.1[0m" 200 -
127.0.0.1 - - [18/Apr/2021 21:42:22] "[37mGET /upload?__debugger__=yes&cmd=resource&f=debugger.js HTTP/1.1[0m" 200 -
127.0.0.1 - - [18/Apr/2021 21:42:22] "[37mGET /upload?__debugger__=yes&cmd=resource&f=console.png HTTP/1.1[0m" 200 -
127.0.0.1 - - [18/Apr/2021 21:42:22] "[37mGET /upload?__debugger__=yes&cmd=resource&f=console.png HTTP/1.1[0m" 200 -
 * Detected change in '/home/slv/doSumn/script/app.py', reloading
 * Restarting with stat
 * Debugger is active!
 * Debugger PIN: 263-977-074
127.0.0.1 - - [18/Apr/2021 21:44:31] "[37mGET / HTTP/1.1[0m" 200 -
<FileStorage: 'pos_neg.csv' ('text/csv')>
127.0.0.1 - - [18/Apr/2021 21:44:35] "[32mPOST /upload HTTP/1.1[0m" 302 -
127.0.0.1 - - [18/Apr/2021 21:44:35] "[37mGET /upload HTTP/1.1[0m" 200 -
 * Detected change in '/home/slv/doSumn/script/app.py', reloading
 * Restarting with stat
 * Debugger is active!
 * Debugger PIN: 263-977-074
 * Detected change in '/home/slv/doSumn/script/app.py', reloading
 * Restarting with stat
 * Debugger is active!
 * Debugger PIN: 263-977-074
 * Detected change in '/home/slv/doSumn/script/main.py', reloading
 * Restarting with stat
 * Debugger is active!
 * Debugger PIN: 263-977-074
 * Detected change in '/home/slv/doSumn/script/main.py', reloading
 * Restarting with stat
 * Debugger is active!
 * Debugger PIN: 263-977-074
 * Detected change in '/home/slv/doSumn/script/app.py', reloading
 * Restarting with stat
 * Debugger is active!
 * Debugger PIN: 263-977-074
 * Detected change in '/home/slv/doSumn/script/app.py', reloading
 * Restarting with stat
 * Debugger is active!
 * Debugger PIN: 263-977-074
 * Detected change in '/home/slv/doSumn/script/app.py', reloading
 * Restarting with stat
 * Debugger is active!
 * Debugger PIN: 263-977-074
127.0.0.1 - - [18/Apr/2021 21:57:11] "[37mPOST /upload HTTP/1.1[0m" 200 -
 * Detected change in '/home/slv/doSumn/script/app.py', reloading
 * Restarting with stat
 * Debugger is active!
 * Debugger PIN: 263-977-074
127.0.0.1 - - [18/Apr/2021 21:57:22] "[37mPOST /upload HTTP/1.1[0m" 200 -
 * Detected change in '/home/slv/doSumn/script/main.py', reloading
 * Restarting with stat
 * Debugger is active!
 * Debugger PIN: 263-977-074
 * Detected change in '/home/slv/doSumn/script/main.py', reloading
 * Restarting with stat
 * Debugger is active!
 * Debugger PIN: 263-977-074
 * Detected change in '/home/slv/doSumn/script/main.py', reloading
 * Restarting with stat
 * Debugger is active!
 * Debugger PIN: 263-977-074
127.0.0.1 - - [18/Apr/2021 22:07:33] "[37mGET / HTTP/1.1[0m" 200 -
127.0.0.1 - - [18/Apr/2021 22:07:48] "[35m[1mPOST /upload HTTP/1.1[0m" 500 -
Traceback (most recent call last):
  File "/home/slv/.local/lib/python3.8/site-packages/flask/app.py", line 2464, in __call__
    return self.wsgi_app(environ, start_response)
  File "/home/slv/.local/lib/python3.8/site-packages/flask/app.py", line 2450, in wsgi_app
    response = self.handle_exception(e)
  File "/home/slv/.local/lib/python3.8/site-packages/flask/app.py", line 1867, in handle_exception
    reraise(exc_type, exc_value, tb)
  File "/home/slv/.local/lib/python3.8/site-packages/flask/_compat.py", line 39, in reraise
    raise value
  File "/home/slv/.local/lib/python3.8/site-packages/flask/app.py", line 2447, in wsgi_app
    response = self.full_dispatch_request()
  File "/home/slv/.local/lib/python3.8/site-packages/flask/app.py", line 1952, in full_dispatch_request
    rv = self.handle_user_exception(e)
  File "/home/slv/.local/lib/python3.8/site-packages/flask/app.py", line 1821, in handle_user_exception
    reraise(exc_type, exc_value, tb)
  File "/home/slv/.local/lib/python3.8/site-packages/flask/_compat.py", line 39, in reraise
    raise value
  File "/home/slv/.local/lib/python3.8/site-packages/flask/app.py", line 1950, in full_dispatch_request
    rv = self.dispatch_request()
  File "/home/slv/.local/lib/python3.8/site-packages/flask/app.py", line 1936, in dispatch_request
    return self.view_functions[rule.endpoint](**req.view_args)
  File "/home/slv/doSumn/script/app.py", line 18, in upload
    result = main.dosumn(input.filename)
  File "/home/slv/doSumn/script/main.py", line 73, in dosumn
    test = util.get_parser_data("uploads/"+filename)
  File "/home/slv/doSumn/script/util.py", line 6, in get_parser_data
    data = pd.read_csv('../' + filename)
  File "/home/slv/.local/lib/python3.8/site-packages/pandas/io/parsers.py", line 610, in read_csv
    return _read(filepath_or_buffer, kwds)
  File "/home/slv/.local/lib/python3.8/site-packages/pandas/io/parsers.py", line 462, in _read
    parser = TextFileReader(filepath_or_buffer, **kwds)
  File "/home/slv/.local/lib/python3.8/site-packages/pandas/io/parsers.py", line 819, in __init__
    self._engine = self._make_engine(self.engine)
  File "/home/slv/.local/lib/python3.8/site-packages/pandas/io/parsers.py", line 1050, in _make_engine
    return mapping[engine](self.f, **self.options)  # type: ignore[call-arg]
  File "/home/slv/.local/lib/python3.8/site-packages/pandas/io/parsers.py", line 1867, in __init__
    self._open_handles(src, kwds)
  File "/home/slv/.local/lib/python3.8/site-packages/pandas/io/parsers.py", line 1362, in _open_handles
    self.handles = get_handle(
  File "/home/slv/.local/lib/python3.8/site-packages/pandas/io/common.py", line 642, in get_handle
    handle = open(
FileNotFoundError: [Errno 2] No such file or directory: '../uploads/class - 1.csv'
127.0.0.1 - - [18/Apr/2021 22:07:48] "[37mGET /upload?__debugger__=yes&cmd=resource&f=debugger.js HTTP/1.1[0m" 200 -
127.0.0.1 - - [18/Apr/2021 22:07:48] "[37mGET /upload?__debugger__=yes&cmd=resource&f=style.css HTTP/1.1[0m" 200 -
127.0.0.1 - - [18/Apr/2021 22:07:48] "[37mGET /upload?__debugger__=yes&cmd=resource&f=jquery.js HTTP/1.1[0m" 200 -
127.0.0.1 - - [18/Apr/2021 22:07:48] "[37mGET /upload?__debugger__=yes&cmd=resource&f=console.png HTTP/1.1[0m" 200 -
127.0.0.1 - - [18/Apr/2021 22:07:48] "[37mGET /upload?__debugger__=yes&cmd=resource&f=console.png HTTP/1.1[0m" 200 -
 * Detected change in '/home/slv/doSumn/script/app.py', reloading
 * Restarting with stat
 * Debugger is active!
 * Debugger PIN: 263-977-074
127.0.0.1 - - [18/Apr/2021 22:10:10] "[37mPOST /upload HTTP/1.1[0m" 200 -
 * Detected change in '/home/slv/doSumn/script/app.py', reloading
 * Restarting with stat
 * Debugger is active!
 * Debugger PIN: 263-977-074
127.0.0.1 - - [18/Apr/2021 22:16:18] "[37mGET / HTTP/1.1[0m" 200 -
127.0.0.1 - - [18/Apr/2021 22:16:24] "[35m[1mPOST /upload HTTP/1.1[0m" 500 -
Traceback (most recent call last):
  File "/home/slv/.local/lib/python3.8/site-packages/flask/app.py", line 2464, in __call__
    return self.wsgi_app(environ, start_response)
  File "/home/slv/.local/lib/python3.8/site-packages/flask/app.py", line 2450, in wsgi_app
    response = self.handle_exception(e)
  File "/home/slv/.local/lib/python3.8/site-packages/flask/app.py", line 1867, in handle_exception
    reraise(exc_type, exc_value, tb)
  File "/home/slv/.local/lib/python3.8/site-packages/flask/_compat.py", line 39, in reraise
    raise value
  File "/home/slv/.local/lib/python3.8/site-packages/flask/app.py", line 2447, in wsgi_app
    response = self.full_dispatch_request()
  File "/home/slv/.local/lib/python3.8/site-packages/flask/app.py", line 1952, in full_dispatch_request
    rv = self.handle_user_exception(e)
  File "/home/slv/.local/lib/python3.8/site-packages/flask/app.py", line 1821, in handle_user_exception
    reraise(exc_type, exc_value, tb)
  File "/home/slv/.local/lib/python3.8/site-packages/flask/_compat.py", line 39, in reraise
    raise value
  File "/home/slv/.local/lib/python3.8/site-packages/flask/app.py", line 1950, in full_dispatch_request
    rv = self.dispatch_request()
  File "/home/slv/.local/lib/python3.8/site-packages/flask/app.py", line 1936, in dispatch_request
    return self.view_functions[rule.endpoint](**req.view_args)
  File "/home/slv/doSumn/script/app.py", line 18, in upload
    return redirect(url_for('.summ', filename = input.filename))
NameError: name 'url_for' is not defined
127.0.0.1 - - [18/Apr/2021 22:16:24] "[37mGET /upload?__debugger__=yes&cmd=resource&f=style.css HTTP/1.1[0m" 200 -
127.0.0.1 - - [18/Apr/2021 22:16:24] "[37mGET /upload?__debugger__=yes&cmd=resource&f=jquery.js HTTP/1.1[0m" 200 -
127.0.0.1 - - [18/Apr/2021 22:16:24] "[37mGET /upload?__debugger__=yes&cmd=resource&f=debugger.js HTTP/1.1[0m" 200 -
127.0.0.1 - - [18/Apr/2021 22:16:24] "[37mGET /upload?__debugger__=yes&cmd=resource&f=console.png HTTP/1.1[0m" 200 -
127.0.0.1 - - [18/Apr/2021 22:16:25] "[37mGET /upload?__debugger__=yes&cmd=resource&f=console.png HTTP/1.1[0m" 200 -
 * Detected change in '/home/slv/doSumn/script/app.py', reloading
 * Restarting with stat
 * Debugger is active!
 * Debugger PIN: 263-977-074
127.0.0.1 - - [18/Apr/2021 22:17:00] "[32mPOST /upload HTTP/1.1[0m" 302 -
127.0.0.1 - - [18/Apr/2021 22:17:24] "[37mGET /summary?filename=class+-+1.csv HTTP/1.1[0m" 200 -
 * Detected change in '/home/slv/doSumn/script/app.py', reloading
 * Restarting with stat
 * Debugger is active!
 * Debugger PIN: 263-977-074
127.0.0.1 - - [18/Apr/2021 22:19:36] "[35m[1mGET /summary?filename=class+-+1.csv HTTP/1.1[0m" 500 -
Traceback (most recent call last):
  File "/home/slv/.local/lib/python3.8/site-packages/flask/app.py", line 2464, in __call__
    return self.wsgi_app(environ, start_response)
  File "/home/slv/.local/lib/python3.8/site-packages/flask/app.py", line 2450, in wsgi_app
    response = self.handle_exception(e)
  File "/home/slv/.local/lib/python3.8/site-packages/flask/app.py", line 1867, in handle_exception
    reraise(exc_type, exc_value, tb)
  File "/home/slv/.local/lib/python3.8/site-packages/flask/_compat.py", line 39, in reraise
    raise value
  File "/home/slv/.local/lib/python3.8/site-packages/flask/app.py", line 2447, in wsgi_app
    response = self.full_dispatch_request()
  File "/home/slv/.local/lib/python3.8/site-packages/flask/app.py", line 1952, in full_dispatch_request
    rv = self.handle_user_exception(e)
  File "/home/slv/.local/lib/python3.8/site-packages/flask/app.py", line 1821, in handle_user_exception
    reraise(exc_type, exc_value, tb)
  File "/home/slv/.local/lib/python3.8/site-packages/flask/_compat.py", line 39, in reraise
    raise value
  File "/home/slv/.local/lib/python3.8/site-packages/flask/app.py", line 1950, in full_dispatch_request
    rv = self.dispatch_request()
  File "/home/slv/.local/lib/python3.8/site-packages/flask/app.py", line 1936, in dispatch_request
    return self.view_functions[rule.endpoint](**req.view_args)
  File "/home/slv/doSumn/script/app.py", line 23, in summ
    filename = session['filename']
  File "/home/slv/.local/lib/python3.8/site-packages/werkzeug/local.py", line 377, in <lambda>
    __getitem__ = lambda x, i: x._get_current_object()[i]
  File "/home/slv/.local/lib/python3.8/site-packages/flask/sessions.py", line 84, in __getitem__
    return super(SecureCookieSession, self).__getitem__(key)
KeyError: 'filename'
127.0.0.1 - - [18/Apr/2021 22:19:36] "[37mGET /summary?__debugger__=yes&cmd=resource&f=style.css HTTP/1.1[0m" 200 -
127.0.0.1 - - [18/Apr/2021 22:19:36] "[37mGET /summary?__debugger__=yes&cmd=resource&f=jquery.js HTTP/1.1[0m" 200 -
127.0.0.1 - - [18/Apr/2021 22:19:36] "[37mGET /summary?__debugger__=yes&cmd=resource&f=debugger.js HTTP/1.1[0m" 200 -
127.0.0.1 - - [18/Apr/2021 22:19:36] "[37mGET /summary?__debugger__=yes&cmd=resource&f=console.png HTTP/1.1[0m" 200 -
127.0.0.1 - - [18/Apr/2021 22:19:36] "[37mGET /summary?__debugger__=yes&cmd=resource&f=console.png HTTP/1.1[0m" 200 -
127.0.0.1 - - [18/Apr/2021 22:19:40] "[35m[1mPOST /upload HTTP/1.1[0m" 500 -
Traceback (most recent call last):
  File "/home/slv/.local/lib/python3.8/site-packages/flask/app.py", line 2464, in __call__
    return self.wsgi_app(environ, start_response)
  File "/home/slv/.local/lib/python3.8/site-packages/flask/app.py", line 2450, in wsgi_app
    response = self.handle_exception(e)
  File "/home/slv/.local/lib/python3.8/site-packages/flask/app.py", line 1867, in handle_exception
    reraise(exc_type, exc_value, tb)
  File "/home/slv/.local/lib/python3.8/site-packages/flask/_compat.py", line 39, in reraise
    raise value
  File "/home/slv/.local/lib/python3.8/site-packages/flask/app.py", line 2447, in wsgi_app
    response = self.full_dispatch_request()
  File "/home/slv/.local/lib/python3.8/site-packages/flask/app.py", line 1952, in full_dispatch_request
    rv = self.handle_user_exception(e)
  File "/home/slv/.local/lib/python3.8/site-packages/flask/app.py", line 1821, in handle_user_exception
    reraise(exc_type, exc_value, tb)
  File "/home/slv/.local/lib/python3.8/site-packages/flask/_compat.py", line 39, in reraise
    raise value
  File "/home/slv/.local/lib/python3.8/site-packages/flask/app.py", line 1950, in full_dispatch_request
    rv = self.dispatch_request()
  File "/home/slv/.local/lib/python3.8/site-packages/flask/app.py", line 1936, in dispatch_request
    return self.view_functions[rule.endpoint](**req.view_args)
  File "/home/slv/doSumn/script/app.py", line 18, in upload
    session['filename'] = input.filename
  File "/home/slv/.local/lib/python3.8/site-packages/werkzeug/local.py", line 350, in __setitem__
    self._get_current_object()[key] = value
  File "/home/slv/.local/lib/python3.8/site-packages/flask/sessions.py", line 102, in _fail
    raise RuntimeError(
RuntimeError: The session is unavailable because no secret key was set.  Set the secret_key on the application to something unique and secret.
127.0.0.1 - - [18/Apr/2021 22:19:40] "[37mGET /upload?__debugger__=yes&cmd=resource&f=style.css HTTP/1.1[0m" 200 -
127.0.0.1 - - [18/Apr/2021 22:19:40] "[37mGET /upload?__debugger__=yes&cmd=resource&f=jquery.js HTTP/1.1[0m" 200 -
127.0.0.1 - - [18/Apr/2021 22:19:40] "[37mGET /upload?__debugger__=yes&cmd=resource&f=debugger.js HTTP/1.1[0m" 200 -
127.0.0.1 - - [18/Apr/2021 22:19:40] "[37mGET /upload?__debugger__=yes&cmd=resource&f=console.png HTTP/1.1[0m" 200 -
 * Detected change in '/home/slv/doSumn/script/app.py', reloading
 * Restarting with stat
 * Debugger is active!
 * Debugger PIN: 263-977-074
127.0.0.1 - - [18/Apr/2021 22:19:57] "[37mGET / HTTP/1.1[0m" 200 -
127.0.0.1 - - [18/Apr/2021 22:20:03] "[32mPOST /upload HTTP/1.1[0m" 302 -
127.0.0.1 - - [18/Apr/2021 22:20:26] "[37mGET /summary?filename=class+-+3.csv HTTP/1.1[0m" 200 -
 * Detected change in '/home/slv/doSumn/script/main.py', reloading
 * Restarting with stat
 * Debugger is active!
 * Debugger PIN: 263-977-074
127.0.0.1 - - [18/Apr/2021 22:21:40] "[37mGET / HTTP/1.1[0m" 200 -
127.0.0.1 - - [18/Apr/2021 22:21:46] "[32mPOST /upload HTTP/1.1[0m" 302 -
127.0.0.1 - - [18/Apr/2021 22:22:01] "[37mGET /summary?filename=class+-+3.csv HTTP/1.1[0m" 200 -
127.0.0.1 - 